Workbook

Sheet 추진성과
A1: 부서별 총괄표 | H1: 2026년 부서별 주요업무 추진성과 이행률
H3: 부서 | I3: 경영지원팀 | J3: 소통혁신팀 | K3: 안전감사실 | L3: 문화체육팀 | M3: 교통사업팀 | N3: 환경지원팀 | O3: 환경사업팀 | P3: 행복나루
A4: 부서명 | B4: 경영목표 | D4: 경영전략 | H4: 과제수(A) | I4: =경영지원팀!$B$60 -> 21 | J4: =소통혁신팀!$B$57 -> 14 | K4: =안전감사실!$B$58 -> 7 | L4: =문화체육팀!$B$60 -> 22 | M4: =교통사업팀!$B$60 -> 13 | N4: =환경지원팀!$B$60 -> 7 | O4: =환경사업팀!$B$59 -> 14 | P4: =행복나루!$B$57 -> 20
A5: 경영지원팀 | B5: 경영평가 "나"등급 이상 | C5: =경영지원팀!$B$38 -> 10 | D5: 엄정한 지휘체계 확립 | E5: =경영지원팀!D38 -> 0 | H5: 완료건(B) | I5: =COUNTIF(경영지원팀!$G$3:$G$28,"추진완료") -> 2 | J5: =COUNTIF(소통혁신팀!$G$3:$G$25,"추진완료") -> 4 | K5: =COUNTIF(안전감사실!$G$3:$G$26,"추진완료") -> 0 | L5: =COUNTIF(문화체육팀!$G$3:$G$28,"추진완료") -> 2 | M5: =COUNTIF(교통사업팀!$G$3:$G$28,"추진완료") -> 5 | N5: =COUNTIF(환경지원팀!$G$3:$G$28,"추진완료") -> 3 | O5: =COUNTIF(환경사업팀!$G$3:$G$27,"추진완료") -> 5 | P5: =COUNTIF(행복나루!$G$3:$G$25,"추진완료") -> 1
D6: 중장기경영 전략계획 수립 | E6: =경영지원팀!D39 -> 3 | H6: 이행완료(B/A) | I6: =I5/I4 -> 0.095238095 | J6: =J5/J4 -> 0.28571429 | K6: =K5/K4 -> 0 | L6: =L5/L4 -> 0.090909091 | M6: =M5/M4 -> 0.38461538 | N6: =N5/N4 -> 0.42857143 | O6: =O5/O4 -> 0.35714286 | P6: =P5/P4 -> 0.05
D7: 건전재정운영 예산집행 투명성 | E7: =경영지원팀!D40 -> 5 | I7: 과제 | J7: =SUM(I4:P4) -> 118 | K7: 건 중 | L7: =SUM(I5:P5) -> 22 | M7: 건 이행 → | N7: 이행완료 | O7: =AVERAGE(I6:P6) -> 0.21152389
D8: 독립적 감사 기능 강화 | E8: =경영지원팀!D40 -> 5 | H8: 평균이행률(%) | I8: =경영지원팀!H31 -> 0.51428571 | J8: =소통혁신팀!H23 -> 0.71142857 | K8: =안전감사실!H14 -> 0.2 | L8: =문화체육팀!H31 -> 0.54545455 | M8: =교통사업팀!H20 -> 0.46153846 | N8: =환경지원팀!H16 -> 0.74285714 | O8: =환경사업팀!H20 -> 0.46428571 | P8: =행복나루!H27 -> 0.61595
D9: 독립적 감사 기능 강화 | E9: =경영지원팀!D41 -> 0 | H9: 자체평가(점) | I9: =경영지원팀!H30 -> 52.631579 | J9: =소통혁신팀!H22 -> 64.166667 | K9: =안전감사실!H13 -> 19.5 | L9: =문화체육팀!H30 -> 55.666667 | M9: =교통사업팀!H19 -> 41.666667 | N9: =환경지원팀!H15 -> 68.888889 | O9: =환경사업팀!H19 -> 39.583333 | P9: =행복나루!H26 -> 63.528
D10: 개인정보 보호 관리 철저 | E10: =경영지원팀!D42 -> 1 | I10: 전 부서 자체 평과 결과 평균 | L10: =AVERAGE(I8:P8) -> 0.53197502 | M10: 이행 | N10: 자체점수 | O10: =AVERAGE(I9:P9) -> 50.703975 | P10: 점
D11: 지역사회공헌 확대 | E11: =경영지원팀!D43 -> 1
B12: 노사화합 청렴도 우수 등급 | C12: =경영지원팀!$B$44 -> 8 | D12: 합리적인 조직관리 | E12: =경영지원팀!D44 -> 7
D13: 합리적 승진 전보제도 | E13: =경영지원팀!D45 -> 1
D14: 노사·노노간 상생문화 구축 | E14: =경영지원팀!D46 -> 0
D15: 환경직 복리후생 점검 및 개선 | E15: =경영지원팀!D47 -> 0
D16: 합리적 보수(임금) 유지 | E16: =경영지원팀!D48 -> 0
B17: 안전사고 제로(ZERO) | C17: =경영지원팀!$B$49 -> 2 | D17: 선제적·체계적 시설관리 운영 | E17: =경영지원팀!D49 -> 0
D18: 노후, 낙후 시설보수 정비 | E18: =경영지원팀!D50 -> 0
D19: 「생활쓰레기 일일수거」 | E19: =경영지원팀!D51 -> 0
D20: 「시설물통합정보관리시스템」 구축 | E20: =경영지원팀!D52 -> 2
D21: 산업안전보건시스템 | E21: =경영지원팀!D53 -> 0
B22: 고객만족도 90% 이상 | C22: =경영지원팀!$B$54 -> 1 | D22: 환경 민원 신속 처리(‘26년 시행) | E22: =경영지원팀!D54 -> 0
D23: 각종 시설물관리 운영 전문화 | E23: =경영지원팀!D55 -> 0
D24: 원활한 주차장 관리 | E24: =경영지원팀!D56 -> 0
D25: 다양한 시민참여 프로그램 운영 | E25: =경영지원팀!D57 -> 0
D26: 광고수익증대·도시미관 조성 | E26: =경영지원팀!D58 -> 0
D27: 노인일자리 창출 및 확대 | E27: =경영지원팀!D59 -> 1
B28: 소계 | C28: =SUM(C5:C27) -> 21 | D28: 소계 | E28: =SUM(E5:E27) -> 26
A29: 소통혁신팀 | B29: 경영평가 "나"등급 이상 | C29: =소통혁신팀!$B$35 -> 7 | D29: 엄정한 지휘체계 확립 | E29: =소통혁신팀!$D35 -> 1
D30: 중장기경영 전략계획 수립 | E30: =소통혁신팀!$D36 -> 3
D31: 건전재정운영 예산집행 투명성 | E31: =소통혁신팀!$D37 -> 2
D32: 독립적 감사 기능 강화 | E32: =소통혁신팀!$D38 -> 0
D33: 개인정보 보호 관리 철저 | E33: =소통혁신팀!$D39 -> 0
D34: 지역사회공헌 확대 | E34: =소통혁신팀!$D40 -> 1
B35: 노사화합 청렴도 우수 등급 | C35: =소통혁신팀!$B$41 -> 5 | D35: 합리적인 조직관리 | E35: =소통혁신팀!$D41 -> 2
D36: 합리적 승진 전보제도 | E36: =소통혁신팀!$D42 -> 0
D37: 노사·노노간 상생문화 구축 | E37: =소통혁신팀!$D43 -> 3
D38: 환경직 복리후생 점검 및 개선 | E38: =소통혁신팀!$D44 -> 0
D39: 합리적 보수(임금) 유지 | E39: =소통혁신팀!$D45 -> 0
B40: 안전사고 제로(ZERO) | C40: =소통혁신팀!$B$46 -> 1 | D40: 선제적·체계적 시설관리 운영 | E40: =소통혁신팀!$D46 -> 1
D41: 노후, 낙후 시설보수 정비 | E41: =소통혁신팀!$D47 -> 0
...

Sheet 부서별 총괄표
A1: 부서별 총괄표
A4: 부서명 | B4: 경영목표 | D4: 경영전략 | F4: 점수(점) | G4: 이행률
A5: 경영지원팀 | B5: 경영평가 "나"등급 이상 | C5: =경영지원팀!$B$38 -> 10 | D5: 엄정한 지휘체계 확립 | E5: =경영지원팀!D38 -> 0 | F5: =추진성과!I9 -> 52.631579 | G5: =추진성과!I6 -> 0.095238095
D6: 중장기경영 전략계획 수립 | E6: =경영지원팀!D39 -> 3
D7: 건전재정운영 예산집행 투명성 | E7: =경영지원팀!D40 -> 5
D8: 독립적 감사 기능 강화 | E8: =경영지원팀!D41 -> 0
D9: 개인정보 보호 관리 철저 | E9: =경영지원팀!D42 -> 1
D10: 지역사회공헌 확대 | E10: =경영지원팀!D43 -> 1
B11: 노사화합 청렴도 우수 등급 | C11: =경영지원팀!$B$44 -> 8 | D11: 합리적인 조직관리 | E11: =경영지원팀!D44 -> 7
D12: 합리적 승진 전보제도 | E12: =경영지원팀!D45 -> 1
D13: 노사·노노간 상생문화 구축 | E13: =경영지원팀!D46 -> 0
D14: 환경직 복리후생 점검 및 개선 | E14: =경영지원팀!D47 -> 0
D15: 합리적 보수(임금) 유지 | E15: =경영지원팀!D48 -> 0
B16: 안전사고 제로(ZERO) | C16: =경영지원팀!$B$49 -> 2 | D16: 선제적·체계적 시설관리 운영 | E16: =경영지원팀!D49 -> 0
D17: 노후, 낙후 시설보수 정비 | E17: =경영지원팀!D50 -> 0
D18: 「생활쓰레기 일일수거」 | E18: =경영지원팀!D51 -> 0
D19: 「시설물통합정보관리시스템」 구축 | E19: =경영지원팀!D52 -> 2
D20: 산업안전보건시스템 | E20: =경영지원팀!D53 -> 0
B21: 고객만족도 90% 이상 | C21: =경영지원팀!$B$54 -> 1 | D21: 환경 민원 신속 처리(‘26년 시행) | E21: =경영지원팀!D54 -> 0
D22: 각종 시설물관리 운영 전문화 | E22: =경영지원팀!D55 -> 0
D23: 원활한 주차장 관리 | E23: =경영지원팀!D56 -> 0
D24: 다양한 시민참여 프로그램 운영 | E24: =경영지원팀!D57 -> 0
D25: 광고수익증대·도시미관 조성 | E25: =경영지원팀!D58 -> 0
D26: 노인일자리 창출 및 확대 | E26: =경영지원팀!D59 -> 1
B27: 소계 | C27: =SUM(C5:C26) -> 21 | D27: 소계 | E27: =SUM(E5:E26) -> 21
A28: 소통혁신팀 | B28: 경영평가 "나"등급 이상 | C28: =소통혁신팀!$B$35 -> 7 | D28: 엄정한 지휘체계 확립 | E28: =소통혁신팀!$D35 -> 1 | F28: =추진성과!J$9 -> 64.166667 | G28: =추진성과!I$6 -> 0.095238095
D29: 중장기경영 전략계획 수립 | E29: =소통혁신팀!$D36 -> 3
D30: 건전재정운영 예산집행 투명성 | E30: =소통혁신팀!$D37 -> 2
D31: 독립적 감사 기능 강화 | E31: =소통혁신팀!$D38 -> 0
D32: 개인정보 보호 관리 철저 | E32: =소통혁신팀!$D39 -> 0
D33: 지역사회공헌 확대 | E33: =소통혁신팀!$D40 -> 1
B34: 노사화합 청렴도 우수 등급 | C34: =소통혁신팀!$B$41 -> 5 | D34: 합리적인 조직관리 | E34: =소통혁신팀!$D41 -> 2
D35: 합리적 승진 전보제도 | E35: =소통혁신팀!$D42 -> 0
D36: 노사·노노간 상생문화 구축 | E36: =소통혁신팀!$D43 -> 3
D37: 환경직 복리후생 점검 및 개선 | E37: =소통혁신팀!$D44 -> 0
D38: 합리적 보수(임금) 유지 | E38: =소통혁신팀!$D45 -> 0
B39: 안전사고 제로(ZERO) | C39: =소통혁신팀!$B$46 -> 1 | D39: 선제적·체계적 시설관리 운영 | E39: =소통혁신팀!$D46 -> 1
D40: 노후, 낙후 시설보수 정비 | E40: =소통혁신팀!$D47 -> 0
D41: 「생활쓰레기 일일수거」 | E41: =소통혁신팀!$D48 -> 0
D42: 「시설물통합정보관리시스템」 구축 | E42: =소통혁신팀!$D49 -> 0
...

Sheet 전체 총괄표
A1: 부서별 총괄표 | H1: 전체 총괄표
A4: 부서명 | B4: 경영목표 | D4: 경영전략 | H4: 경영목표 | J4: 경영전략
A5: 경영지원팀 | B5: 경영평가 "나"등급 이상 | C5: =경영지원팀!$B$38 -> 10 | D5: 엄정한 지휘체계 확립 | E5: =경영지원팀!D38 -> 0 | H5: 경영평가 "나"등급 이상 | I5: =C5+C28+C51+C74+C97+C120+C143+C166 -> 40 | J5: 엄정한 지휘체계 확립 | K5: =E5+E28+E51+E74+E97+E120+E143+E166 -> 4 | L5: =SUM(K5:K10)-I5 -> 0
D6: 중장기경영 전략계획 수립 | E6: =경영지원팀!D39 -> 3 | J6: 중장기경영 전략계획 수립 | K6: =E6+E29+E52+E75+E98+E121+E144+E167 -> 13
D7: 건전재정운영 예산집행 투명성 | E7: =경영지원팀!D40 -> 5 | J7: 건전재정운영 예산집행 투명성 | K7: =E7+E30+E53+E76+E99+E122+E145+E168 -> 7
D8: 독립적 감사 기능 강화 | E8: =경영지원팀!D41 -> 0 | J8: 독립적 감사 기능 강화 | K8: =E8+E31+E54+E77+E100+E123+E146+E169 -> 2
D9: 개인정보 보호 관리 철저 | E9: =경영지원팀!D42 -> 1 | J9: 개인정보 보호 관리 철저 | K9: =E9+E32+E55+E78+E101+E124+E147+E170 -> 3
D10: 지역사회공헌 확대 | E10: =경영지원팀!D43 -> 1 | J10: 지역사회공헌 확대 | K10: =E10+E33+E56+E79+E102+E125+E148+E171 -> 11
B11: 노사화합 청렴도 우수 등급 | C11: =경영지원팀!$B$44 -> 8 | D11: 합리적인 조직관리 | E11: =경영지원팀!D44 -> 7 | H11: 노사화합 청렴도 우수 등급 | I11: =C11+C34+C57+C80+C103+C126+C149+C172 -> 23 | J11: 합리적인 조직관리 | K11: =E11+E34+E57+E80+E103+E126+E149+E172 -> 13 | L11: =SUM(K11:K15)-I11 -> 0
D12: 합리적 승진 전보제도 | E12: =경영지원팀!D45 -> 1 | J12: 합리적 승진 전보제도 | K12: =E12+E35+E58+E81+E104+E127+E150+E173 -> 1
D13: 노사·노노간 상생문화 구축 | E13: =경영지원팀!D46 -> 0 | J13: 노사·노노간 상생문화 구축 | K13: =E13+E36+E59+E82+E105+E128+E151+E174 -> 7
D14: 환경직 복리후생 점검 및 개선 | E14: =경영지원팀!D47 -> 0 | J14: 환경직 복리후생 점검 및 개선 | K14: =E14+E37+E60+E83+E106+E129+E152+E175 -> 2
D15: 합리적 보수(임금) 유지 | E15: =경영지원팀!D48 -> 0 | J15: 합리적 보수(임금) 유지 | K15: =E15+E38+E61+E84+E107+E130+E153+E176 -> 0
B16: 안전사고 제로(ZERO) | C16: =경영지원팀!$B$49 -> 2 | D16: 선제적·체계적 시설관리 운영 | E16: =경영지원팀!D49 -> 0 | H16: 안전사고 제로(ZERO) | I16: =C16+C39+C62+C85+C108+C131+C154+C177 -> 18 | J16: 선제적·체계적 시설관리 운영 | K16: =E16+E39+E62+E85+E108+E131+E154+E177 -> 6 | L16: =SUM(K16:K20)-I16 -> 0
D17: 노후, 낙후 시설보수 정비 | E17: =경영지원팀!D50 -> 0 | J17: 노후, 낙후 시설보수 정비 | K17: =E17+E40+E63+E86+E109+E132+E155+E178 -> 1
D18: 「생활쓰레기 일일수거」 | E18: =경영지원팀!D51 -> 0 | J18: 「생활쓰레기 일일수거」 | K18: =E18+E41+E64+E87+E110+E133+E156+E179 -> 3
D19: 「시설물통합정보관리시스템」 구축 | E19: =경영지원팀!D52 -> 2 | J19: 「시설물통합정보관리시스템」 구축 | K19: =E19+E42+E65+E88+E111+E134+E157+E180 -> 2
D20: 산업안전보건시스템 | E20: =경영지원팀!D53 -> 0 | J20: 산업안전보건시스템 | K20: =E20+E43+E66+E89+E112+E135+E158+E181 -> 6
B21: 고객만족도 90% 이상 | C21: =경영지원팀!$B$54 -> 1 | D21: 환경 민원 신속 처리(‘26년 시행) | E21: =경영지원팀!D54 -> 0 | H21: 고객만족도 90% 이상 | I21: =C21+C44+C67+C90+C113+C136+C159+C182 -> 37 | J21: 환경 민원 신속 처리(‘26년 시행) | K21: =E21+E44+E67+E90+E113+E136+E159+E182 -> 0 | L21: =SUM(K21:K26)-I21 -> 0
D22: 각종 시설물관리 운영 전문화 | E22: =경영지원팀!D55 -> 0 | J22: 각종 시설물관리 운영 전문화 | K22: =E22+E45+E68+E91+E114+E137+E160+E183 -> 10
D23: 원활한 주차장 관리 | E23: =경영지원팀!D56 -> 0 | J23: 원활한 주차장 관리 | K23: =E23+E46+E69+E92+E115+E138+E161+E184 -> 4
D24: 다양한 시민참여 프로그램 운영 | E24: =경영지원팀!D57 -> 0 | J24: 다양한 시민참여 프로그램 운영 | K24: =E24+E47+E70+E93+E116+E139+E162+E185 -> 20
D25: 광고수익증대·도시미관 조성 | E25: =경영지원팀!D58 -> 0 | J25: 광고수익증대·도시미관 조성 | K25: =E25+E48+E71+E94+E117+E140+E163+E186 -> 1
D26: 노인일자리 창출 및 확대 | E26: =경영지원팀!D59 -> 1 | J26: 노인일자리 창출 및 확대 | K26: =E26+E49+E72+E95+E118+E141+E164+E187 -> 2
B27: 소계 | C27: =SUM(C5:C26) -> 21 | D27: 소계 | E27: =SUM(E5:E26) -> 21 | H27: 소계 | I27: =SUM(I5:I26) -> 118 | J27: 소계 | K27: =SUM(K5:K26) -> 118
A28: 소통혁신팀 | B28: 경영평가 "나"등급 이상 | C28: =소통혁신팀!$B$35 -> 7 | D28: 엄정한 지휘체계 확립 | E28: =소통혁신팀!$D35 -> 1
D29: 중장기경영 전략계획 수립 | E29: =소통혁신팀!$D36 -> 3
D30: 건전재정운영 예산집행 투명성 | E30: =소통혁신팀!$D37 -> 2
D31: 독립적 감사 기능 강화 | E31: =소통혁신팀!$D38 -> 0
D32: 개인정보 보호 관리 철저 | E32: =소통혁신팀!$D39 -> 0
D33: 지역사회공헌 확대 | E33: =소통혁신팀!$D40 -> 1
B34: 노사화합 청렴도 우수 등급 | C34: =소통혁신팀!$B$41 -> 5 | D34: 합리적인 조직관리 | E34: =소통혁신팀!$D41 -> 2
D35: 합리적 승진 전보제도 | E35: =소통혁신팀!$D42 -> 0
D36: 노사·노노간 상생문화 구축 | E36: =소통혁신팀!$D43 -> 3
D37: 환경직 복리후생 점검 및 개선 | E37: =소통혁신팀!$D44 -> 0
D38: 합리적 보수(임금) 유지 | E38: =소통혁신팀!$D45 -> 0
B39: 안전사고 제로(ZERO) | C39: =소통혁신팀!$B$46 -> 1 | D39: 선제적·체계적 시설관리 운영 | E39: =소통혁신팀!$D46 -> 1
D40: 노후, 낙후 시설보수 정비 | E40: =소통혁신팀!$D47 -> 0
D41: 「생활쓰레기 일일수거」 | E41: =소통혁신팀!$D48 -> 0
D42: 「시설물통합정보관리시스템」 구축 | E42: =소통혁신팀!$D49 -> 0
...

Sheet 경영지원팀
A1: 경영지원팀 2026년 주요업무계획 추진현황 보고
A2: 연번 | B2: 경영목표 | C2: 전략과제 | D2: 사업 구분 | E2: 추진과제 | F2: 배점 | G2: 이행현황(%) | I2: 점수 | J2: 추진내용 | K2: 문서번호 | L2: 추진일 | M2: 비 고
A3: 1 | B3: 경영평가 "나"등급 이상 | C3: =C39 -> 중장기경영 전략계획 수립 | D3: 지속 | E3: 국민의 알권리 보장 및 국민참여 확대를 위한 정보공개 | F3: 10 | G3: 추진중 | H3: 0.5 | I3: 5 | J3: 정보공개 업무 추진 중 | M3: 연중상시
A4: 2 | D4: 지속 | E4: 통합경영공시 현행화 실시 | F4: 10 | G4: 추진중 | H4: 0.5 | I4: 5 | J4: 항목별 통합경영공시 클린아이 현행화 실시 | K4: - | L4: 수시, 분기, 반기, 연간 | M4: 클린아이 연간 경영공시 완료
A5: 3 | D5: 지속 | E5: 사전정보공표 항목별 현행화 실시 | F5: 10 | G5: 추진중 | H5: 0.3 | I5: 3 | J5: 사전공표정보 확인 및 업데이트 실시 | K5: - | L5: 수시 | M5: 9월 일괄 현행화 예정
A6: 4 | C6: 개인정보 보호 관리 철저 | D6: 지속 | E6: 공공기관 개인정보 관리수준 진단 80점 이상 달성 | F6: 5 | G6: 추진중 | H6: 0.1 | I6: 0.5
A7: 5 | C7: =C40 -> 건전재정운영 예산집행 투명성 | D7: 지속 | E7: 예산 집행 투명성 강화 | F7: 10 | G7: 추진중 | H7: 0.5 | I7: 5 | J7: 상시 모니터링 실시, 각 부서 예산회계 집행오류 정정 안내 | K7: - | L7: 상시
A8: 6 | D8: 지속 | E8: 재무구조 개선을 위한 부채비율 감축 계획 | F8: 10 | G8: 추진중 | H8: 0.1 | I8: 1
A9: 7 | D9: 지속 | E9: 근태 시스템 안정화를 통한 통한 급여의 고도화 | F9: 10 | G9: 추진중 | H9: 0.5 | I9: 5
A10: 8 | D10: 지속 | E10: 효율적인 급·상여 관리를 위한 급여 및 수당 테이블 설정 | F10: 5 | G10: 추진중 | H10: 0.5 | I10: 2.5
A11: 9 | D11: 신규 | E11: 계약 투명성 확립을 위한 전자계약 추진 | F11: 10 | G11: 추진중 | H11: 0.5 | I11: 5 | J11: 중소기업간 경쟁제품 적절성 검토 시행중, 표준화 규정 개정 예정 | K11: 경영-905, 1510, 2304, 4327 | L11: 분기별 등
A12: 10 | C12: =C43 -> 지역사회공헌 확대 | D12: 지속 | E12: 지역상생을 위한 우선구매 실적 달성 추진 | F12: 10 | G12: 추친중 | H12: 0.5 | I12: 5 | J12: 공공구매 실적 관리 중 | L12: 연중상시
A13: 11 | B13: 노사화합 청렴도 우수 등급 | C13: =C45 -> 합리적 승진 전보제도 | D13: 지속 | E13: 직무중심 인사관리 추진 고도화 | F13: 10 | G13: 추진중 | H13: 0.6 | I13: 6 | J13: 1단계, 2단계 완료 및 3단계 관련 컨설팅 진행중 | K13: 경영-3844 | L13: 46185
A14: 12 | C14: =C44 -> 합리적인 조직관리 | D14: 지속 | E14: 인사 관련 공단 제 규정 정비 추진 | F14: 10 | G14: 추진중 | H14: 0.3 | I14: 3 | J14: 직무중심인사관리 적용 관련 부분개정 추진예정 | K14: 소통-2190 | L14: 46223
A15: 13 | D15: 지속 | E15: 임원추천위원회 구성 및 운영 | F15: 10 | G15: 추진중 | H15: 0.5 | I15: 5 | J15: 비상임이사 추천을 위한 임원추천위원회 개최 완료 | K15: 경영-4485 | L15: 46211
A16: 14 | D16: 신규 | E16: 직원 복무 만족도 증진을 위한 복무제도 활성화 | F16: 10 | G16: 추진중 | H16: 0.5 | I16: 5 | J16: 유급휴가 사용촉진 1차 완료 | K16: 경영-4301 | L16: 46204
A17: 15 | D17: 신규 | E17: 일ㆍ가정 양립을 위한 저출산 극복 제도운영 활성화 | F17: 10 | G17: 추진중 | H17: 0.4 | I17: 4 | J17: 출산휴가, 육아휴직 통합신청제 도입 완료 | K17: 경영-4497 | L17: 45880
A18: 16 | D18: 신규 | E18: 디지털 행정을 위한 전자이미지 공인 양식 표준화 | F18: 10 | G18: 추진중 | H18: 1 | I18: 10 | J18: 구현 가능 여부 확인 중 | L18: 하반기 중 시행 예정
A19: 17 | D19: 지속 | E19: 직무중심 역량 강화 교육훈련 운영 | F19: 5 | G19: 추진중 | H19: 0.5 | I19: 2.5 | J19: 공단 임직원 법정교육 및 직무교육 상시 진행 | K19: 경영-1936, 2694 | L19: 2026.3.23.~
A20: 18 | D20: 지속 | E20: 안전관리자·보건관리자 채용으로 전문인력 확대 | F20: 10 | G20: 추진완료 | H20: 1 | I20: 10 | J20: 안전·보건관리자 채용 완료 | K20: 경영-43, 1761 | L20: 2026.1.2., '2026.3.13.
A21: 19 | B21: 안전사고 제로(ZERO) | C21: =C52 -> 「시설물통합정보관리시스템」 구축 | D21: 지속 | E21: 통합정보시스템(그룹웨어+ERP) 구축 | F21: 10 | G21: 추진중 | H21: 0.5 | I21: 5
A22: 20 | D22: 지속 | E22: FMS시스템 도입을 위한 공단 자산 파악 | F22: 5 | G22: 추진중 | H22: 0.5 | I22: 2.5
A23: 21 | B23: 고객만족도 90% 이상 | C23: =C59 -> 노인일자리 창출 및 확대 | D23: 지속 | E23: 사회형평적 인재 채용으로 취업 소외계층 일자리 창출 | F23: 10 | G23: 추진완료 | H23: 1 | I23: 10 | J23: 사회형평적 인재 채용 완료 | K23: 경영-1098, 1318, 3272 | L23: 2026.2.11., '2026.2.24., 2026.5.14. | M23: 보훈 채용 의무고용비율 6% -> 4% 변경완료 및 고용률 달성 완료 장애인인턴 채용 및 고용률 달성 완료 청년의무고용비율(일반직) 달성 완료
F29: 총점 | G29: 점수 | H29: 환산점수(100점만점)
F30: =SUM(F3:F23) -> 190 | G30: =SUM(I3:I26) -> 100 | H30: =G30/F30*100 -> 52.631579
H31: =AVERAGE($H$3:H23) -> 0.51428571
C33: 지속여부 | D33: 지속
D34: =COUNTIF(D3:D32,$D$33) -> 17
D35: 신규
D36: =COUNTIF(D3:D34,$D$35) -> 4
A37: 경영목표 | C37: 경영전략
A38: 경영평가 "나"등급 이상 | B38: =SUMPRODUCT(--(LOOKUP(ROW($B$2:$B$22),ROW($B$2:$B$23)/($B$2:$B$23<>""),$B$2:$B$23)=A38)) -> 10 | C38: 엄정한 지휘체계 확립 | D38: =SUMPRODUCT(--(LOOKUP(ROW($C$2:$C$22),ROW($C$2:$C$22)/($C$2:$C$22<>""),$C$2:$C$22)=C38)) -> 0 | E38: =SUM(D38:D43)-B38 -> 0
C39: 중장기경영 전략계획 수립 | D39: =SUMPRODUCT(--(LOOKUP(ROW($C$2:$C$22),ROW($C$2:$C$22)/($C$2:$C$22<>""),$C$2:$C$22)=C39)) -> 3
C40: 건전재정운영 예산집행 투명성 | D40: =SUMPRODUCT(--(LOOKUP(ROW($C$2:$C$22),ROW($C$2:$C$22)/($C$2:$C$22<>""),$C$2:$C$22)=C40)) -> 5
C41: 독립적 감사 기능 강화 | D41: =SUMPRODUCT(--(LOOKUP(ROW($C$2:$C$22),ROW($C$2:$C$22)/($C$2:$C$22<>""),$C$2:$C$22)=C41)) -> 0
C42: 개인정보 보호 관리 철저 | D42: =SUMPRODUCT(--(LOOKUP(ROW($C$2:$C$22),ROW($C$2:$C$22)/($C$2:$C$22<>""),$C$2:$C$22)=C42)) -> 1
C43: 지역사회공헌 확대 | D43: =SUMPRODUCT(--(LOOKUP(ROW($C$2:$C$22),ROW($C$2:$C$22)/($C$2:$C$22<>""),$C$2:$C$22)=C43)) -> 1
A44: 노사화합 청렴도 우수 등급 | B44: =SUMPRODUCT(--(LOOKUP(ROW($B$2:$B$22),ROW($B$2:$B$23)/($B$2:$B$23<>""),$B$2:$B$23)=A44)) -> 8 | C44: 합리적인 조직관리 | D44: =SUMPRODUCT(--(LOOKUP(ROW($C$2:$C$22),ROW($C$2:$C$22)/($C$2:$C$22<>""),$C$2:$C$22)=C44)) -> 7 | E44: =SUM(D44:D48)-B44 -> 0
C45: 합리적 승진 전보제도 | D45: =SUMPRODUCT(--(LOOKUP(ROW($C$2:$C$22),ROW($C$2:$C$22)/($C$2:$C$22<>""),$C$2:$C$22)=C45)) -> 1
C46: 노사·노노간 상생문화 구축 | D46: =SUMPRODUCT(--(LOOKUP(ROW($C$2:$C$22),ROW($C$2:$C$22)/($C$2:$C$22<>""),$C$2:$C$22)=C46)) -> 0
...

Sheet 소통혁신팀
A1: 소통혁신팀 2026년 주요업무계획 추진현황 보고
A2: 연번 | B2: 경영목표 | C2: 전략과제 | D2: 사업 구분 | E2: 추진과제 | F2: 배점 | G2: 이행현황(%) | I2: 점수 | J2: 추진내용 | K2: 문서번호 | L2: 추진일 | M2: 비 고
A3: 1 | B3: =A35 -> 경영평가 "나"등급 이상 | C3: =C35 -> 엄정한 지휘체계 확립 | D3: 지속 | E3: 공단 청렴경영을 위한 외부이사 참여 이사회 운영 | F3: 10 | G3: 추진중 | H3: 1 | I3: 5 | J3: 2026년 이사회 5회 개최(7월 기준) | K3: 소-477, 1012,1572,1864,2361 | L3: 2026.1월 ~ 7월 | M3: 서희
A4: 2 | C4: =C36 -> 중장기경영 전략계획 수립 | D4: 지속 | E4: 2026년 “경영평가 우수등급” 달성 | F4: 5 | G4: 추진완료 | H4: 1 | I4: 1 | J4: 2026년도 경영평가 라등급 | L4: 2026. 8. | M4: 유규태
A5: 3 | D5: 신규 | E5: “경영평가 우수등급” 달성을 위한 정량지표 중점관리 | F5: 10 | G5: 추진중 | H5: 0.5 | I5: 4 | J5: 2026년도 경영평가 정량 38.87점 | L5: 2026.8. | M5: 유규태
A6: 4 | D6: 신규 | E6: 독서경영 우수 직장 인증 추진 | F6: 10 | G6: 추진중 | H6: 0.5 | I6: 5 | J6: 독서경영인증 신청서 제출완료 | K6: 소-2340 | L6: 2026.7.31. | M6: 서희
A7: 5 | C7: =C37 -> 건전재정운영 예산집행 투명성 | D7: 지속 | E7: 지역경제 활력 제고를 위한 사회적 역할 적극적 역할 강화 | F7: 10 | G7: 추진중 | H7: 0.5 | I7: 5 | J7: 상반기 적극집행(신속집행) 목표액 초과 달성 | K7: 소-2000 | L7: 2026.6.30. | M7: 유기림
A8: 6 | D8: 지속 | E8: 유휴자금 운용 다각화로 수익률 개선 | F8: 10 | G8: 추진완료 | H8: 1 | I8: 10 | J8: 유휴자금 총 6차 예치 | K8: 소-2401 | L8: 2026.8.6. | M8: 유기림
A9: 7 | C9: =C40 -> 지역사회공헌 확대 | D9: 지속 | E9: 지역상생·협력 지표 달성을 위한 지역사회공헌인정제 재인증 | F9: 5 | G9: 추진완료 | H9: 1 | I9: 5 | J9: 지역사회공헌 인정제 | K9: 소-2071 | L9: 2026.7. | M9: 유기림
A10: 8 | B10: =A41 -> 노사화합 청렴도 우수 등급 | C10: =C41 -> 합리적인 조직관리 | D10: 신규 | E10: 경영 리더십 강화를 위한 미래혁신위원회 운영 | F10: 10 | G10: 추진중 | H10: 0.5 | I10: 6 | J10: 상반기 미래혁신위원회 추진완료 | K10: 소-1991 | L10: 2026.7.2. | M10: 서희
A11: 10 | D11: 신규 | E11: BSC 성과평가시스템 운영 | F11: 10 | G11: 추진중 | H11: 0.8 | I11: 8 | J11: 성과편람(초안) 작성. 노조 및 직원 의견 수렴중 | K11: 소-2477 | M11: 유규태
A12: 11 | C12: =C43 -> 노사·노노간 상생문화 구축 | D12: 지속 | E12: 직원 소통 강화를 통한 직장문화 개선 | F12: 5 | G12: 추진중 | H12: 0 | M12: 이상혁
A13: 12 | D13: 지속 | E13: 상생의 노사관계 구축을 위한 노사협의체 운영 | F13: 15 | G13: 추진중 | H13: 0.66 | I13: 11 | J13: 노사협의회 2회 운영, 공단 교섭 20회 시행 | K13: 소통혁신팀-1959 외 | L13: 상시 | M13: 이상혁
A14: 13 | D14: 지속 | E14: 노사·노노간 상생문화 구축을 위한 공단 규정 개정 | F14: 10 | G14: 추진완료 | H14: 1 | I14: 10 | J14: 공단 규정 및 내규 일괄개정 완료 | K14: 소통혁신팀-1901 소통혁신팀-1946 | L14: 2026. 6월 | M14: 이상혁
A15: 14 | B15: =A46 -> 안전사고 제로(ZERO) | C15: =C46 -> 선제적·체계적 시설관리 운영 | D15: 지속 | E15: 탄소중립 실현을 위한 지속가능 친환경 경영 강화 | F15: 5 | G15: 추진증 | H15: 0.5 | I15: 2 | J15: 탄소중립 기술지원 사업 추진 | K15: 소-1754 | M15: 유규태
A16: 15 | B16: =A51 -> 고객만족도 90% 이상 | C16: =C54 -> 다양한 시민참여 프로그램 운영 | D16: 지속 | E16: 경영평가 “나”등급 이상 달성을 위한 소통채널 관리 | F16: 5 | G16: 추진중 | H16: 1 | I16: 5 | J16: 보도자료 및 홍보자료 20회 이상 배포 | M16: 유기림
F21: 총점 | G21: 점수 | H21: 환산점수(100점만점)
F22: =SUM(F3:F16) -> 120 | G22: =SUM(I3:I16) -> 77 | H22: =G22/F22*100 -> 64.166667
H23: =AVERAGE(H3:H16) -> 0.71142857
C30: 지속여부 | D30: 지속
D31: =COUNTIF(D3:D29,$D$30) -> 10
D32: 신규
D33: =COUNTIF(D3:D31,$D$32) -> 4
A34: 경영목표 | C34: 경영전략
A35: 경영평가 "나"등급 이상 | B35: =SUMPRODUCT(--(LOOKUP(ROW($B$2:$B$19),ROW($B$2:$B$19)/($B$2:$B$19<>""),$B$2:$B$19)=A35)) -> 7 | C35: 엄정한 지휘체계 확립 | D35: =SUMPRODUCT(--(LOOKUP(ROW($C$2:$C$16),ROW($C$2:$C$16)/($C$2:$C$16<>""),$C$2:$C$16)=C35)) -> 1 | E35: =SUM(D35:D40)-B35 -> 0
C36: 중장기경영 전략계획 수립 | D36: =SUMPRODUCT(--(LOOKUP(ROW($C$2:$C$16),ROW($C$2:$C$16)/($C$2:$C$16<>""),$C$2:$C$16)=C36)) -> 3
C37: 건전재정운영 예산집행 투명성 | D37: =SUMPRODUCT(--(LOOKUP(ROW($C$2:$C$16),ROW($C$2:$C$16)/($C$2:$C$16<>""),$C$2:$C$16)=C37)) -> 2
C38: 독립적 감사 기능 강화 | D38: =SUMPRODUCT(--(LOOKUP(ROW($C$2:$C$16),ROW($C$2:$C$16)/($C$2:$C$16<>""),$C$2:$C$16)=C38)) -> 0
C39: 개인정보 보호 관리 철저 | D39: =SUMPRODUCT(--(LOOKUP(ROW($C$2:$C$16),ROW($C$2:$C$16)/($C$2:$C$16<>""),$C$2:$C$16)=C39)) -> 0
C40: 지역사회공헌 확대 | D40: =SUMPRODUCT(--(LOOKUP(ROW($C$2:$C$16),ROW($C$2:$C$16)/($C$2:$C$16<>""),$C$2:$C$16)=C40)) -> 1
A41: 노사화합 청렴도 우수 등급 | B41: =SUMPRODUCT(--(LOOKUP(ROW($B$2:$B$19),ROW($B$2:$B$19)/($B$2:$B$19<>""),$B$2:$B$19)=A41)) -> 5 | C41: 합리적인 조직관리 | D41: =SUMPRODUCT(--(LOOKUP(ROW($C$2:$C$16),ROW($C$2:$C$16)/($C$2:$C$16<>""),$C$2:$C$16)=C41)) -> 2 | E41: =SUM(D41:D45)-B41 -> 0
C42: 합리적 승진 전보제도 | D42: =SUMPRODUCT(--(LOOKUP(ROW($C$2:$C$16),ROW($C$2:$C$16)/($C$2:$C$16<>""),$C$2:$C$16)=C42)) -> 0
C43: 노사·노노간 상생문화 구축 | D43: =SUMPRODUCT(--(LOOKUP(ROW($C$2:$C$16),ROW($C$2:$C$16)/($C$2:$C$16<>""),$C$2:$C$16)=C43)) -> 3
C44: 환경직 복리후생 점검 및 개선 | D44: =SUMPRODUCT(--(LOOKUP(ROW($C$2:$C$16),ROW($C$2:$C$16)/($C$2:$C$16<>""),$C$2:$C$16)=C44)) -> 0
C45: 합리적 보수(임금) 유지 | D45: =SUMPRODUCT(--(LOOKUP(ROW($C$2:$C$16),ROW($C$2:$C$16)/($C$2:$C$16<>""),$C$2:$C$16)=C45)) -> 0
A46: 안전사고 제로(ZERO) | B46: =SUMPRODUCT(--(LOOKUP(ROW($B$2:$B$19),ROW($B$2:$B$19)/($B$2:$B$19<>""),$B$2:$B$19)=A46)) -> 1 | C46: 선제적·체계적 시설관리 운영 | D46: =SUMPRODUCT(--(LOOKUP(ROW($C$2:$C$16),ROW($C$2:$C$16)/($C$2:$C$16<>""),$C$2:$C$16)=C46)) -> 1 | E46: =SUM(D46:D50)-B46 -> 0
C47: 노후, 낙후 시설보수 정비 | D47: =SUMPRODUCT(--(LOOKUP(ROW($C$2:$C$16),ROW($C$2:$C$16)/($C$2:$C$16<>""),$C$2:$C$16)=C47)) -> 0
C48: 「생활쓰레기 일일수거」 | D48: =SUMPRODUCT(--(LOOKUP(ROW($C$2:$C$16),ROW($C$2:$C$16)/($C$2:$C$16<>""),$C$2:$C$16)=C48)) -> 0
C49: 「시설물통합정보관리시스템」 구축 | D49: =SUMPRODUCT(--(LOOKUP(ROW($C$2:$C$16),ROW($C$2:$C$16)/($C$2:$C$16<>""),$C$2:$C$16)=C49)) -> 0
C50: 산업안전보건시스템 | D50: =SUMPRODUCT(--(LOOKUP(ROW($C$2:$C$16),ROW($C$2:$C$16)/($C$2:$C$16<>""),$C$2:$C$16)=C50)) -> 0
...

Sheet 안전감사실
A1: 안전감사실 2026년 주요업무계획 추진현황 보고
A2: 연번 | B2: 경영목표 | C2: 전략과제 | D2: 사업 구분 | E2: 추진과제 | F2: 배점 | G2: 이행현황(%) | I2: 점수 | J2: 추진내용 | K2: 문서번호 | L2: 추진일 | M2: 비 고
A3: 1 | B3: =A36 -> 경영평가 "나"등급 이상 | C3: =C37 -> 중장기경영 전략계획 수립 | D3: 지속 | E3: 인권경영시스템 사후관리 운영 | F3: 7 | G3: 추진중 | H3: 0.1 | I3: =F3*H3 -> 0.7 | J3: 인권경영시스템 심사 준비중('26.9월 추진)
A4: 2 | C4: =C36 -> 엄정한 지휘체계 확립 | D4: 지속 | E4: 공단 윤리·인권경영 체계적 관리 실천 | F4: 7 | G4: 추진중 | H4: 0.4 | I4: =F4*H4 -> 2.8 | J4: 2026년 윤리경영 추진계획 2026년 인권경영 추진계획 2026년 인권경영 실무위원회 운영 계획 2026년 제1회 윤리인권경영위원회 개최('26.8월 추진) 2026년 인권영향평가 추진 준비중('26.10월 추진) | K4: 안전감사실-341 안전감사실-184 안전감사실-827 | L4: 2026.02.02. 2026.01.19. 2026.04.16.
A5: 3 | D5: 지속 | E5: 공단 부패방지경영시스템(ISO37001) 사후관리 | F5: 7 | G5: 추진중 | H5: 0.1 | I5: =F5*H5 -> 0.7 | J5: 부패방지경영시스템 심사 준비중('26. 9월 추진)
A6: 4 | C6: =C39 -> 독립적 감사 기능 강화 | D6: 지속 | E6: 2026년도 공단 자체감사 운영 | F6: 9 | G6: 추진중 | H6: 0.5 | I6: =F6*H6 -> 4.5 | J6: 2026년 자체감사 추진 계획 2026년 설명절 복무강화 2026년 종량제봉투 재고관리 실태 확인점검 계획 2026년 음주운전 특정감사 2026년 복무감사반운영(3,4,5,6월) | K6: 안전감사실-105 안전감사실-351,776 안전감사실-803 안전감사실-1498 안전감사실-797,1245,1247,1431 | L6: 2026.01.12. 2026.03.23. 2026.04.15. 2026.07.20.
A7: 5 | B7: =A47 -> 안전사고 제로(ZERO) | C7: =C51 -> 산업안전보건시스템 | D7: 지속/중점 | E7: 최고경영자의 안전보건활동 참여 | F7: 10 | G7: 추진중 | H7: 0.1 | I7: =F7*H7 -> 1 | J7: 최고경영자의 안전보건활동 준비중
A8: 6 | D8: 신규/중점 | E8: 안전보건 QR 신고제 운영 | F8: 10 | G8: 추진중 | H8: 0.1 | I8: =F8*H8 -> 1 | J8: 안전보건 QR 신고제 운영 준비중
A9: 7 | D9: 지속/중점 | E9: 비상대응 매뉴얼 구축 및 대응훈련 체계 마련 | F9: 10 | G9: 추진중 | H9: 0.1 | I9: =F9*H9 -> 1 | J9: 비상대응 매뉴얼 구축 및 대응훈련 체계 준비중
F12: 총점 | G12: 점수 | H12: 환산점수(100점만점)
F13: =SUM(F3:F9) -> 60 | G13: =SUM(I3:I9) -> 11.7 | H13: =G13/F13*100 -> 19.5
H14: =AVERAGE(H3:H9) -> 0.2
C31: 지속여부 | D31: 지속
D32: =COUNTIF(D3:D30,$D$31) -> 4
D33: 신규
D34: =COUNTIF(D3:D32,$D$33) -> 0
A35: 경영목표 | C35: 경영전략
A36: 경영평가 "나"등급 이상 | B36: =SUMPRODUCT(--(LOOKUP(ROW($B$2:$B$20),ROW($B$2:$B$20)/($B$2:$B$20<>""),$B$2:$B$20)=A36)) -> 4 | C36: 엄정한 지휘체계 확립 | D36: =SUMPRODUCT(--(LOOKUP(ROW($C$2:$C$9),ROW($C$2:$C$9)/($C$2:$C$9<>""),$C$2:$C$9)=C36)) -> 2 | E36: =SUM(D36:D41)-B36 -> 0
C37: 중장기경영 전략계획 수립 | D37: =SUMPRODUCT(--(LOOKUP(ROW($C$2:$C$9),ROW($C$2:$C$9)/($C$2:$C$9<>""),$C$2:$C$9)=C37)) -> 1
C38: 건전재정운영 예산집행 투명성 | D38: =SUMPRODUCT(--(LOOKUP(ROW($C$2:$C$9),ROW($C$2:$C$9)/($C$2:$C$9<>""),$C$2:$C$9)=C38)) -> 0
C39: 독립적 감사 기능 강화 | D39: =SUMPRODUCT(--(LOOKUP(ROW($C$2:$C$9),ROW($C$2:$C$9)/($C$2:$C$9<>""),$C$2:$C$9)=C39)) -> 1
C40: 개인정보 보호 관리 철저 | D40: =SUMPRODUCT(--(LOOKUP(ROW($C$2:$C$9),ROW($C$2:$C$9)/($C$2:$C$9<>""),$C$2:$C$9)=C40)) -> 0
C41: 지역사회공헌 확대 | D41: =SUMPRODUCT(--(LOOKUP(ROW($C$2:$C$9),ROW($C$2:$C$9)/($C$2:$C$9<>""),$C$2:$C$9)=C41)) -> 0
A42: 노사화합 청렴도 우수 등급 | B42: =SUMPRODUCT(--(LOOKUP(ROW($B$2:$B$20),ROW($B$2:$B$20)/($B$2:$B$20<>""),$B$2:$B$20)=A42)) -> 0 | C42: 합리적인 조직관리 | D42: =SUMPRODUCT(--(LOOKUP(ROW($C$2:$C$9),ROW($C$2:$C$9)/($C$2:$C$9<>""),$C$2:$C$9)=C42)) -> 0 | E42: =SUM(D42:D46)-B42 -> 0
C43: 합리적 승진 전보제도 | D43: =SUMPRODUCT(--(LOOKUP(ROW($C$2:$C$9),ROW($C$2:$C$9)/($C$2:$C$9<>""),$C$2:$C$9)=C43)) -> 0
C44: 노사·노노간 상생문화 구축 | D44: =SUMPRODUCT(--(LOOKUP(ROW($C$2:$C$9),ROW($C$2:$C$9)/($C$2:$C$9<>""),$C$2:$C$9)=C44)) -> 0
C45: 환경직 복리후생 점검 및 개선 | D45: =SUMPRODUCT(--(LOOKUP(ROW($C$2:$C$9),ROW($C$2:$C$9)/($C$2:$C$9<>""),$C$2:$C$9)=C45)) -> 0
C46: 합리적 보수(임금) 유지 | D46: =SUMPRODUCT(--(LOOKUP(ROW($C$2:$C$9),ROW($C$2:$C$9)/($C$2:$C$9<>""),$C$2:$C$9)=C46)) -> 0
A47: 안전사고 제로(ZERO) | B47: =SUMPRODUCT(--(LOOKUP(ROW($B$2:$B$9),ROW($B$2:$B$9)/($B$2:$B$9<>""),$B$2:$B$9)=A47)) -> 3 | C47: 선제적·체계적 시설관리 운영 | D47: =SUMPRODUCT(--(LOOKUP(ROW($C$2:$C$9),ROW($C$2:$C$9)/($C$2:$C$9<>""),$C$2:$C$9)=C47)) -> 0 | E47: =SUM(D47:D51)-B47 -> 0
C48: 노후, 낙후 시설보수 정비 | D48: =SUMPRODUCT(--(LOOKUP(ROW($C$2:$C$9),ROW($C$2:$C$9)/($C$2:$C$9<>""),$C$2:$C$9)=C48)) -> 0
C49: 「생활쓰레기 일일수거」 | D49: =SUMPRODUCT(--(LOOKUP(ROW($C$2:$C$9),ROW($C$2:$C$9)/($C$2:$C$9<>""),$C$2:$C$9)=C49)) -> 0
C50: 「시설물통합정보관리시스템」 구축 | D50: =SUMPRODUCT(--(LOOKUP(ROW($C$2:$C$9),ROW($C$2:$C$9)/($C$2:$C$9<>""),$C$2:$C$9)=C50)) -> 0
C51: 산업안전보건시스템 | D51: =SUMPRODUCT(--(LOOKUP(ROW($C$2:$C$9),ROW($C$2:$C$9)/($C$2:$C$9<>""),$C$2:$C$9)=C51)) -> 3
A52: 고객만족도 90% 이상 | B52: =SUMPRODUCT(--(LOOKUP(ROW($B$2:$B$17),ROW($B$2:$B$17)/($B$2:$B$17<>""),$B$2:$B$17)=A52)) -> 0 | C52: 환경 민원 신속 처리(‘26년 시행) | D52: =SUMPRODUCT(--(LOOKUP(ROW($C$2:$C$9),ROW($C$2:$C$9)/($C$2:$C$9<>""),$C$2:$C$9)=C52)) -> 0 | E52: =SUM(D52:D57)-B52 -> 0
C53: 각종 시설물관리 운영 전문화 | D53: =SUMPRODUCT(--(LOOKUP(ROW($C$2:$C$9),ROW($C$2:$C$9)/($C$2:$C$9<>""),$C$2:$C$9)=C53)) -> 0
C54: 원활한 주차장 관리 | D54: =SUMPRODUCT(--(LOOKUP(ROW($C$2:$C$9),ROW($C$2:$C$9)/($C$2:$C$9<>""),$C$2:$C$9)=C54)) -> 0
C55: 다양한 시민참여 프로그램 운영 | D55: =SUMPRODUCT(--(LOOKUP(ROW($C$2:$C$9),ROW($C$2:$C$9)/($C$2:$C$9<>""),$C$2:$C$9)=C55)) -> 0
C56: 광고수익증대·도시미관 조성 | D56: =SUMPRODUCT(--(LOOKUP(ROW($C$2:$C$9),ROW($C$2:$C$9)/($C$2:$C$9<>""),$C$2:$C$9)=C56)) -> 0
C57: 노인일자리 창출 및 확대 | D57: =SUMPRODUCT(--(LOOKUP(ROW($C$2:$C$9),ROW($C$2:$C$9)/($C$2:$C$9<>""),$C$2:$C$9)=C57)) -> 0
B58: =SUM(B36:B57) -> 7 | D58: =SUM(D36:D57) -> 7

Sheet 문화체육팀
A1: 문화체육팀 2026년 주요업무계획 추진현황 보고
A2: 연번 | B2: 경영목표 | C2: 전략과제 | D2: 사업 구분 | E2: 추진과제 | F2: 배점 | G2: 이행현황(%) | I2: 점수 | J2: 추진내용 | K2: 문서번호 | L2: 추진일 | M2: 비 고
A3: 1 | B3: 경영평가 "나"등급 이상 | C3: 중장기경영 전략계획 수립 | D3: 지속 | E3: 시설관리팀 시설물 유지관리 중장기·단기 계획 수립 | F3: 10 | G3: 추진완료 | H3: 1 | I3: 10 | J3: 공단 비전에 따른 문화체육팀 중장기 경영 계획 | K3: 문화체육팀-1003 | L3: 2026.2.10.
A4: 2 | C4: 지역사회공헌 확대 | D4: 신규 | E4: 문화체육팀 시설물 이용고객과 함께하는 공익캠페인 활동 | F4: 4 | G4: 추진중 | H4: 0.5 | I4: 2
A5: 3 | D5: 지속 | E5: 문화체육팀 주요성과 우수사례 공유·전파 | F5: 10 | G5: 추진중 | H5: 0.5 | I5: 5
A6: 4 | D6: 신규 | E6: 지방소멸 극복을 위한 빛고을센터 한시적 이용료 할인 추진 | F6: 4 | G6: 추진중 | H6: 0.5 | I6: 2
A7: 5 | B7: 안전사고 제로(ZERO) | C7: 산업안전보건시스템 | D7: 신규 | E7: 문화체육팀 폭염 및 한파 예방 교육 활동 실시 | F7: 10 | G7: 추진중 | H7: 0.5 | I7: 5 | J7: 문화체육팀 여름철 폭엽 대비 안전사고 예방 추진 계획 | K7: 문화체육팀-5217 | L7: 2026.7.24.
A8: 6 | D8: 지속 | E8: FMS고도화를 통한 시설물의 체계적인 안전·유지관리 실시 | F8: 10 | G8: 추진중 | H8: 0.5 | I8: 5 | K8: 문화체육팀-1003 | L8: 2026.2.10.
A9: 7 | D9: 지속 | E9: 재난안전관리 예방활동 및 대응능력 강화를 위한 안전교육 | F9: 10 | G9: 추진중 | H9: 0.5 | I9: 5
A10: 8 | B10: 고객만족도 90% 이상 | C10: 각종 시설물관리 운영 전문화 | D10: 지속 | E10: 문화체육팀 기동수선반 운영 | F10: 10 | G10: 추진중 | H10: 0.5 | I10: 5 | K10: 문화체육팀-1225 문화체육팀-1840 문화체육팀-2619 문화체육팀-3385 문화체육팀-4512 문화체육팀-5167 | L10: 2026.2.23. 2026.3.17. 2026.4.15. 2026.5.15. 2026.6.30. 2026.7.23.
A11: 9 | D11: 신규 | E11: 외부기관 연계형 시설점검 및 평가위원단 운영 | F11: 6 | G11: 추진중 | H11: 0.5 | I11: 3 | J11: 빛고을국민체육센터 기계설비 성능점검 실시 결과보고 | K11: 문화체육팀-5082 | L11: 2026.7.20.
A12: 10 | C12: 다양한 시민참여 프로그램 운영 | D12: 신규 | E12: 시민참여 확대를 위한 신규 프로그램(피클볼) 운영 | F12: 7 | G12: 추진완료 | H12: 1 | I12: 7 | J12: 첨단다목적체육센터 피클볼 무료강습 운영 | K12: 문화체육팀-2267 | L12: 2026.4.1.
A13: 11 | D13: 지속 | E13: 첨단다목적체육센터 이용객과의 소통의 시간 운영 | F13: 7 | G13: 추진중 | H13: 0.5 | I13: 3.5 | J13: 첨단다목적체육센터 고객만족도 조사 및 프로그램 강사 만족도 조사 계획 | K13: 문화체육팀-5204 | L13: 2026.7.24.
A14: 12 | D14: 지속 | E14: 수완문화체육센터 운영 효율화를 위한 강사간담회 개최 | F14: 7 | G14: 추진중 | H14: 0.5 | I14: 3.5 | J14: 수완문화체육센터 고객만족도 조사 및 프로그램 강사 만족도 조사 계획 | K14: 문화체육팀-4885 | L14: 2026.7.13.
A15: 13 | D15: 지속 | E15: 수완문화체육센터 회원과 함께 만드는 이용자 간담회 개최 | F15: 7 | G15: 추진중 | H15: 0.5 | I15: 3.5 | J15: 수완문화체육센터 고객만족도 조사 및 프로그램 강사 만족도 조사 계획 | K15: 문화체육팀-4885 | L15: 2026.7.13.
A16: 14 | D16: 지속 | E16: 수완문화체육센터 강좌실 환경개선 | F16: 5 | G16: 추진중 | H16: 0.5 | I16: 2.5
A17: 15 | D17: 지속 | E17: 빛고을국민체육센터 프로그램 활성화를 위한 강사 간담회 | F17: 7 | G17: 추진중 | H17: 0.5 | I17: 3.5
A18: 16 | D18: 지속 | E18: 빛고을국민체육센터 주민의견 반영 확대를 위한 간담회 | F18: 7 | G18: 추진중 | H18: 0.5 | I18: 3.5 | J18: 빛고을 관리 운영 변경 이용객 간담회, 배드민턴 간담회 | K18: 문화체육팀-2857 문화체육팀-3031 | L18: 2026.4.23. 2026.4.30.
A19: 17 | D19: 지속 | E19: 이용객과 함께하는 체육시설 환경정비 및 캠페인 실시 | F19: 10 | G19: 추진중 | H19: 0.5 | I19: 5
A20: 18 | D20: 지속 | E20: 첨단다목적체육센터 유휴시간 활용 배구 무료프로그램 운영 | F20: 6 | G20: 추진중 | H20: 0.5 | I20: 3 | J20: 광산구체육회 생활체육지도자 현장활동 체육시설 이용에 따른 업무 협조 요청 | K20: 문화체육팀-262 | L20: 2026.1.13.
A21: 19 | D21: 지속 | E21: 유관기관 협력, 빛고을국민체육센터 무료 체육강좌 운영 | F21: 3 | G21: 추진중 | H21: 0.5 | I21: 1.5 | J21: 수영 무료프로그램 운영계획(안) | K21: 문화체육팀-267 | L21: 2026.1.13.
A22: 20 | D22: 지속 | E22: 수완문화체육센터 운영 강좌 연계 문화공연 서비스 추진 | F22: 3 | G22: 추진중 | H22: 0.5 | I22: 1.5
A23: 21 | D23: 지속 | E23: 수완문화체육센터 광산구 체육회 연계 무료 강좌 운영 | F23: 4 | G23: 추진중 | H23: 0.5 | I23: 2 | J23: 광산구체육회 생활체육지도자 현장활동 체육시설 이용에 따른 업무 협조 요청 | K23: 문화체육팀-262 | L23: 2026.1.13.
A24: 22 | D24: 신규 | E24: 빛고을국민체육센터 무료 안전체험교육 실시 | F24: 3 | G24: 추진중 | H24: 0.5 | I24: 1.5
F29: 총점 | G29: 점수 | H29: 환산점수(100점만점)
F30: =SUM(F3:F24) -> 150 | G30: =SUM(I3:I24) -> 83.5 | H30: =G30/F30*100 -> 55.666667
H31: =AVERAGE($H$3:H26) -> 0.54545455
C33: 지속여부 | D33: 지속
D34: =COUNTIF(D3:D32,$D$33) -> 16
D35: 신규
D36: =COUNTIF(D3:D34,$D$35) -> 6
A37: 경영목표 | C37: 경영전략
A38: 경영평가 "나"등급 이상 | B38: =SUMPRODUCT(--(LOOKUP(ROW($B$2:$B$24),ROW($B$2:$B$24)/($B$2:$B$24<>""),$B$2:$B$24)=A38)) -> 4 | C38: 엄정한 지휘체계 확립 | D38: =SUMPRODUCT(--(LOOKUP(ROW($C$2:$C$24),ROW($C$2:$C$24)/($C$2:$C$24<>""),$C$2:$C$24)=C38)) -> 0 | E38: =SUM(D38:D43)-B38 -> 0
C39: 중장기경영 전략계획 수립 | D39: =SUMPRODUCT(--(LOOKUP(ROW($C$2:$C$24),ROW($C$2:$C$24)/($C$2:$C$24<>""),$C$2:$C$24)=C39)) -> 1
C40: 건전재정운영 예산집행 투명성 | D40: =SUMPRODUCT(--(LOOKUP(ROW($C$2:$C$24),ROW($C$2:$C$24)/($C$2:$C$24<>""),$C$2:$C$24)=C40)) -> 0
C41: 독립적 감사 기능 강화 | D41: =SUMPRODUCT(--(LOOKUP(ROW($C$2:$C$24),ROW($C$2:$C$24)/($C$2:$C$24<>""),$C$2:$C$24)=C41)) -> 0
C42: 개인정보 보호 관리 철저 | D42: =SUMPRODUCT(--(LOOKUP(ROW($C$2:$C$24),ROW($C$2:$C$24)/($C$2:$C$24<>""),$C$2:$C$24)=C42)) -> 0
C43: 지역사회공헌 확대 | D43: =SUMPRODUCT(--(LOOKUP(ROW($C$2:$C$24),ROW($C$2:$C$24)/($C$2:$C$24<>""),$C$2:$C$24)=C43)) -> 3
A44: 노사화합 청렴도 우수 등급 | B44: =SUMPRODUCT(--(LOOKUP(ROW($B$2:$B$22),ROW($B$2:$B$24)/($B$2:$B$24<>""),$B$2:$B$24)=A44)) -> 0 | C44: 합리적인 조직관리 | D44: =SUMPRODUCT(--(LOOKUP(ROW($C$2:$C$24),ROW($C$2:$C$24)/($C$2:$C$24<>""),$C$2:$C$24)=C44)) -> 0 | E44: =SUM(D44:D48)-B44 -> 0
C45: 합리적 승진 전보제도 | D45: =SUMPRODUCT(--(LOOKUP(ROW($C$2:$C$24),ROW($C$2:$C$24)/($C$2:$C$24<>""),$C$2:$C$24)=C45)) -> 0
...

Sheet 교통사업팀
A1: 교통사업팀 2026년 주요업무계획 추진현황 보고
A2: 연번 | B2: 경영목표 | C2: 전략과제 | D2: 사업 구분 | E2: 추진과제 | F2: 배점 | G2: 이행현황(%) | I2: 점수 | J2: 추진내용 | K2: 문서번호 | L2: 추진일 | M2: 비 고
A3: 1 | B3: =A38 -> 경영평가 "나"등급 이상 | C3: =C43 -> 지역사회공헌 확대 | D3: 지속 | E3: 옥외광고시설물 활용, 지역사회공헌 활동 강화 | F3: 5 | G3: 추진완료 | H3: 1 | I3: =F3*H3 -> 5 | J3: 지역사회공언 및 공익홍보를 위한 업무협약 현수막 제작 2026년 옥외광고 시설물활용 지역사회 공헌활동(공익활동) 결과보고 | K3: 교통사업팀-353 교통사업팀-1249 | L3: 2026.1.29. 2026.4.16.
A4: 2 | B4: =A49 -> 안전사고 제로(ZERO) | C4: =C49 -> 선제적·체계적 시설관리 운영 | D4: 지속 | E4: 쾌적하고 안전한 주차 서비스 제공을 위한 전수조사 | F4: 5 | G4: 추진중 | H4: 0.5 | I4: =F4*H4 -> 2.5 | J4: 2026년 상반기 공영주차장(56개소) 전수조사 결과보고 2026년 상반기 전통시장 공영주차장(5개소) 전수조사 결과보고 | K4: 교통사업팀-1963 교통사업팀-1957 | L4: 2026.6.18. 2026.6.18.
A5: 3 | D5: 지속 | E5: 안전하고 신속한 유개승강장 유지관리 체계 구축 | F5: 5 | G5: 추진완료 | H5: 1 | I5: =F5*H5 -> 5 | J5: 2026년 교통사업팀 관리운영 종합계획(안) | K5: 교통사업팀-981 | L5: 2026.3.25.
A6: 4 | D6: 지속 | E6: 안전취약계층 안전 보장을 위한 공영주차장 내 방범 활동 | F6: 5 | G6: 추진중 | H6: 0 | I6: =F6*H6 -> 0
A7: 5 | D7: 신규 | E7: 공영주차장 전기자동차 충전시설 모니터링시스템 구축 | F7: 5 | G7: 추진완료 | H7: 1 | I7: =F7*H7 -> 5 | J7: 공영주차장 4개소 전기자동차 충전소 모니터링시스템 구축 계획 전통시장공영주차장 전기자동차 충전소 모니터링시스템 구축 계획 전통시장공영주차장 전기자동차 충전소 모니터링시스템 구축 결과보고 | K7: 교통사업팀-92 교통사업팀-101 교통사업팀-180 | L7: 2026.1.12. 2026.1.12. 2026.1.16.
A8: 6 | C8: =C50 -> 노후, 낙후 시설보수 정비 | D8: 신규 | E8: 생애주기비용 분석 중심 교통광고시설 관리체계 구축 | F8: 10 | G8: 추진중 | H8: 0 | I8: =F8*H8 -> 0
A9: 7 | B9: =A54 -> 고객만족도 90% 이상 | C9: =C56 -> 원활한 주차장 관리 | D9: 지속 | E9: 올바른 주차질서 확립을 위한 교통안전 캠페인 추진 | F9: 10 | G9: 추진중 | H9: 0 | I9: =F9*H9 -> 0
A10: 8 | D10: 지속 | E10: 공영주차장 시설물 민원신속처리반 운영 | F10: 10 | G10: 추진중 | H10: 0.5 | I10: =F10*H10 -> 5 | J10: 2026년 대행사업비 절감을 위한 교통사업팀 기동수선반 활용 계획(안) | K10: 교통사업팀-90 | L10: 20261.12.
A11: 9 | D11: 지속 | E11: 공영주차장 주차요금 사전무인정산기 확대 구축 | F11: 10 | G11: 추진중 | H11: 0 | I11: =F11*H11 -> 0
A12: 10 | D12: 신규 | E12: 이기종 무인정산장비 연동을 통한 스마트주차시스템 고도화 | F12: 10 | G12: 추진완료 | H12: 1 | I12: =F12*H12 -> 10 | J12: 공영주차장 스마트주차시스템 고도화 추진 중간보고 공영주차장 스마트주차시스템 고도화 추진사항 요약보고 | K12: 교통사업팀-87 교통사업팀-586 | L12: 2026.1.12. 2026.2.20.
A13: 11 | C13: =C58 -> 광고수익증대·도시미관 조성 | D13: 지속 | E13: 불법광고물 단속 및 근절 캠페인 실시 | F13: 5 | G13: 추진중 | H13: 0 | I13: =F13*H13 -> 0
A14: 12 | C14: =C57 -> 다양한 시민참여 프로그램 운영 | D14: 지속 | E14: 공영주차장 이용객 무상 차량정비 서비스 제공 | F14: 5 | G14: 추진중 | H14: 0 | I14: =F14*H14 -> 0
A15: 13 | C15: =C59 -> 노인일자리 창출 및 확대 | D15: 지속 | E15: 지역사회 공헌을 위한 사회 취약계층 일자리 창출 | F15: 5 | G15: 추진완료 | H15: 1 | I15: =F15*H15 -> 5 | J15: ＇지역상생 발전과 안전한 교통시설 환경조성을 위한＇우리동네 교통시설 안전 지킴이 업무협약 추진 | K15: 교통사업팀-57 | L15: 2026.1.09
F18: 총점 | G18: 점수 | H18: 환산점수(100점만점)
F19: =SUM(F3:F15) -> 90 | G19: =SUM(I3:I15) -> 37.5 | H19: =G19/F19*100 -> 41.666667
H20: =AVERAGE($H$3:H15) -> 0.46153846
C33: 지속여부 | D33: 지속
D34: =COUNTIF(D3:D32,$D$33) -> 10
D35: 신규
D36: =COUNTIF(D3:D34,$D$35) -> 3
A37: 경영목표 | C37: 경영전략
A38: 경영평가 "나"등급 이상 | B38: =SUMPRODUCT(--(LOOKUP(ROW($B$2:$B$15),ROW($B$2:$B$15)/($B$2:$B$15<>""),$B$2:$B$15)=A38)) -> 1 | C38: 엄정한 지휘체계 확립 | D38: =SUMPRODUCT(--(LOOKUP(ROW($C$2:$C$15),ROW($C$2:$C$15)/($C$2:$C$15<>""),$C$2:$C$15)=C38)) -> 0 | E38: =SUM(D38:D43)-B38 -> 0
C39: 중장기경영 전략계획 수립 | D39: =SUMPRODUCT(--(LOOKUP(ROW($C$2:$C$15),ROW($C$2:$C$15)/($C$2:$C$15<>""),$C$2:$C$15)=C39)) -> 0
C40: 건전재정운영 예산집행 투명성 | D40: =SUMPRODUCT(--(LOOKUP(ROW($C$2:$C$15),ROW($C$2:$C$15)/($C$2:$C$15<>""),$C$2:$C$15)=C40)) -> 0
C41: 독립적 감사 기능 강화 | D41: =SUMPRODUCT(--(LOOKUP(ROW($C$2:$C$15),ROW($C$2:$C$15)/($C$2:$C$15<>""),$C$2:$C$15)=C41)) -> 0
C42: 개인정보 보호 관리 철저 | D42: =SUMPRODUCT(--(LOOKUP(ROW($C$2:$C$15),ROW($C$2:$C$15)/($C$2:$C$15<>""),$C$2:$C$15)=C42)) -> 0
C43: 지역사회공헌 확대 | D43: =SUMPRODUCT(--(LOOKUP(ROW($C$2:$C$15),ROW($C$2:$C$15)/($C$2:$C$15<>""),$C$2:$C$15)=C43)) -> 1
A44: 노사화합 청렴도 우수 등급 | B44: =SUMPRODUCT(--(LOOKUP(ROW($B$2:$B$15),ROW($B$2:$B$15)/($B$2:$B$15<>""),$B$2:$B$15)=A44)) -> 0 | C44: 합리적인 조직관리 | D44: =SUMPRODUCT(--(LOOKUP(ROW($C$2:$C$15),ROW($C$2:$C$15)/($C$2:$C$15<>""),$C$2:$C$15)=C44)) -> 0 | E44: =SUM(D44:D48)-B44 -> 0
C45: 합리적 승진 전보제도 | D45: =SUMPRODUCT(--(LOOKUP(ROW($C$2:$C$15),ROW($C$2:$C$15)/($C$2:$C$15<>""),$C$2:$C$15)=C45)) -> 0
C46: 노사·노노간 상생문화 구축 | D46: =SUMPRODUCT(--(LOOKUP(ROW($C$2:$C$15),ROW($C$2:$C$15)/($C$2:$C$15<>""),$C$2:$C$15)=C46)) -> 0
C47: 환경직 복리후생 점검 및 개선 | D47: =SUMPRODUCT(--(LOOKUP(ROW($C$2:$C$15),ROW($C$2:$C$15)/($C$2:$C$15<>""),$C$2:$C$15)=C47)) -> 0
C48: 합리적 보수(임금) 유지 | D48: =SUMPRODUCT(--(LOOKUP(ROW($C$2:$C$15),ROW($C$2:$C$15)/($C$2:$C$15<>""),$C$2:$C$15)=C48)) -> 0
A49: 안전사고 제로(ZERO) | B49: =SUMPRODUCT(--(LOOKUP(ROW($B$2:$B$15),ROW($B$2:$B$15)/($B$2:$B$15<>""),$B$2:$B$15)=A49)) -> 5 | C49: 선제적·체계적 시설관리 운영 | D49: =SUMPRODUCT(--(LOOKUP(ROW($C$2:$C$15),ROW($C$2:$C$15)/($C$2:$C$15<>""),$C$2:$C$15)=C49)) -> 4 | E49: =SUM(D49:D53)-B49 -> 0
C50: 노후, 낙후 시설보수 정비 | D50: =SUMPRODUCT(--(LOOKUP(ROW($C$2:$C$15),ROW($C$2:$C$15)/($C$2:$C$15<>""),$C$2:$C$15)=C50)) -> 1
C51: 「생활쓰레기 일일수거」 | D51: =SUMPRODUCT(--(LOOKUP(ROW($C$2:$C$15),ROW($C$2:$C$15)/($C$2:$C$15<>""),$C$2:$C$15)=C51)) -> 0
C52: 「시설물통합정보관리시스템」 구축 | D52: =SUMPRODUCT(--(LOOKUP(ROW($C$2:$C$15),ROW($C$2:$C$15)/($C$2:$C$15<>""),$C$2:$C$15)=C52)) -> 0
C53: 산업안전보건시스템 | D53: =SUMPRODUCT(--(LOOKUP(ROW($C$2:$C$15),ROW($C$2:$C$15)/($C$2:$C$15<>""),$C$2:$C$15)=C53)) -> 0
A54: 고객만족도 90% 이상 | B54: =SUMPRODUCT(--(LOOKUP(ROW($B$2:$B$15),ROW($B$2:$B$15)/($B$2:$B$15<>""),$B$2:$B$15)=A54)) -> 7 | C54: 환경 민원 신속 처리(‘26년 시행) | D54: =SUMPRODUCT(--(LOOKUP(ROW($C$2:$C$15),ROW($C$2:$C$15)/($C$2:$C$15<>""),$C$2:$C$15)=C54)) -> 0 | E54: =SUM(D54:D59)-B54 -> 0
...

Sheet 환경지원팀
A1: 환경지원팀 2026년 주요업무계획 추진현황 보고
A2: 연번 | B2: 경영목표 | C2: 전략과제 | D2: 사업 구분 | E2: 추진과제 | F2: 배점 | G2: 이행현황(%) | I2: 점수 | J2: 추진내용 | K2: 문서번호 | L2: 추진일 | M2: 비 고
A3: 1 | B3: =A38 -> 경영평가 "나"등급 이상 | C3: 중장기경영 전략계획 수립 | D3: 지속 | E3: 환경직근로자 채용 및 복무관리 규정 체계적 정비 | F3: 10 | G3: 추진중 | H3: 0.7 | I3: 7 | J3: 공단 보수규정 외 제규정 1건 개정(안) 의견 제출 환경직근로자 채용 및 복무관리 규정 개정(안) 환경직 복무관리규정 일부개정 건에 대한 의견청취 | K3: 환경지원팀-201 환경지원팀-491 환경지원팀-1170 | L3: 2026.2.3.' 2026.3.16. 2026.7.10. | M3: 심진희 / 10점
A4: 2 | D4: 지속 | E4: 법과 원칙이 바로 선 선진 노사관행 및 복무기강 확립 | F4: 10 | G4: 추진완료 | H4: 1 | I4: 10 | J4: 2026년 노동조합 근로시간 면제 신청에 따른 검토 및 회신완료 2026년 4월 7일자 환경사업팀으로 업무이관 | K4: 환경지원팀-4 외 다수 | L4: 2026.1.7. | M4: 심진희 / 10점
A5: 3 | D5: 지속 | E5: 효율적인 급·상여 관리를 위한 급여 및 수당 테이블 설정 | F5: 10 | G5: 추진완료 | H5: 1 | I5: 10 | J5: 환경직 급여 및 수당 산정자료 사전 정비(안정화) 완료 | K5: 환경지원팀-218 외 다수 | L5: 2026..2.5. | M5: 정여진 / 10점
A6: 4 | D6: 신규 | E6: 환경지원팀 신설에 따른 업무 확정 및 체계화 | F6: 30 | G6: 추진중 | H6: 0.5 | I6: 15 | J6: 징계위원회 체계적립 완료(2026.8월 징계위원회 개최예정) 통상임금 반영완료(변경 시 즉시 조치예정) 내부평가급 개선 검토(안) 미수립(2026.8월 수립예정) 호봉재획정 신청 6건 검토완료 및 계획 수립 완료(2026.8월 위원회 개최 예정) | K6: 환경지원팀-1170 | L6: 2026.7.10. | M6: 김일천 / 30점
A7: 5 | C7: 개인정보 보호 관리 철저 | D7: 지속 | E7: 환경직 대상 법정교육훈련 운영 | F7: 10 | G7: 추진중 | H7: 0.5 | I7: 5 | J7: 상반기 산업안전보건교육 및 법정교육 추진완료 2026년 하반기 정기 산업안전보건교육 계획수립 완료 | K7: 환경직원팀-1155 | L7: 2026.7.08. | M7: 정여진 / 10점
A8: 6 | D8: 신규 | E8: 환경직 직원 급여 오류집행 제로화 추진 | F8: 10 | G8: 추진완료 | H8: 1 | I8: 10 | J8: 2026.6.30.기준 급여 오류집행 1건 및 오류조치 완료 | K8: 환경지원팀-278 | L8: 2026.2.11. | M8: 정여진 / 10점
A9: 7 | C9: 독립적 감사 기능 강화 | D9: 지속 | E9: 노․사가 함께하는 활기찬 조직문화 조성 | F9: 10 | G9: 추진중 | H9: 0.5 | I9: 5 | J9: 한마음행사, 상반기 가족의날, 정년퇴직(상반기) 완료 | K9: 환경지원팀-1096 | L9: 2026.6.30. | M9: 심진희 / 10점
F14: 총점 | G14: 점수 | H14: 환산점수(100점만점)
F15: =SUM(F3:F9) -> 90 | G15: =SUM(I3:I9) -> 62 | H15: =G15/F15*100 -> 68.888889
F16: 평균이행률 | H16: =AVERAGE($H$3:H11) -> 0.74285714
C33: 지속여부 | D33: 지속
D34: =COUNTIF(D3:D32,$D$33) -> 5
D35: 신규
D36: =COUNTIF(D3:D34,$D$35) -> 2
A37: 경영목표 | C37: 경영전략
A38: 경영평가 "나"등급 이상 | B38: =SUMPRODUCT(--(LOOKUP(ROW($B$2:$B$9),ROW($B$2:$B$9)/($B$2:$B$9<>""),$B$2:$B$9)=A38)) -> 7 | C38: 엄정한 지휘체계 확립 | D38: =SUMPRODUCT(--(LOOKUP(ROW($C$2:$C$9),ROW($C$2:$C$9)/($C$2:$C$9<>""),$C$2:$C$9)=C38)) -> 0 | E38: =SUM(D38:D43)-B38 -> 0
C39: 중장기경영 전략계획 수립 | D39: =SUMPRODUCT(--(LOOKUP(ROW($C$2:$C$9),ROW($C$2:$C$9)/($C$2:$C$9<>""),$C$2:$C$9)=C39)) -> 4
C40: 건전재정운영 예산집행 투명성 | D40: =SUMPRODUCT(--(LOOKUP(ROW($C$2:$C$9),ROW($C$2:$C$9)/($C$2:$C$9<>""),$C$2:$C$9)=C40)) -> 0
C41: 독립적 감사 기능 강화 | D41: =SUMPRODUCT(--(LOOKUP(ROW($C$2:$C$9),ROW($C$2:$C$9)/($C$2:$C$9<>""),$C$2:$C$9)=C41)) -> 1
C42: 개인정보 보호 관리 철저 | D42: =SUMPRODUCT(--(LOOKUP(ROW($C$2:$C$9),ROW($C$2:$C$9)/($C$2:$C$9<>""),$C$2:$C$9)=C42)) -> 2
C43: 지역사회공헌 확대 | D43: =SUMPRODUCT(--(LOOKUP(ROW($C$2:$C$9),ROW($C$2:$C$9)/($C$2:$C$9<>""),$C$2:$C$9)=C43)) -> 0
A44: 노사화합 청렴도 우수 등급 | B44: =SUMPRODUCT(--(LOOKUP(ROW($B$2:$B$9),ROW($B$2:$B$9)/($B$2:$B$9<>""),$B$2:$B$9)=A44)) -> 0 | C44: 합리적인 조직관리 | D44: =SUMPRODUCT(--(LOOKUP(ROW($C$2:$C$9),ROW($C$2:$C$9)/($C$2:$C$9<>""),$C$2:$C$9)=C44)) -> 0 | E44: =SUM(D44:D48)-B44 -> 0
C45: 합리적 승진 전보제도 | D45: =SUMPRODUCT(--(LOOKUP(ROW($C$2:$C$9),ROW($C$2:$C$9)/($C$2:$C$9<>""),$C$2:$C$9)=C45)) -> 0
C46: 노사·노노간 상생문화 구축 | D46: =SUMPRODUCT(--(LOOKUP(ROW($C$2:$C$9),ROW($C$2:$C$9)/($C$2:$C$9<>""),$C$2:$C$9)=C46)) -> 0
C47: 환경직 복리후생 점검 및 개선 | D47: =SUMPRODUCT(--(LOOKUP(ROW($C$2:$C$9),ROW($C$2:$C$9)/($C$2:$C$9<>""),$C$2:$C$9)=C47)) -> 0
C48: 합리적 보수(임금) 유지 | D48: =SUMPRODUCT(--(LOOKUP(ROW($C$2:$C$9),ROW($C$2:$C$9)/($C$2:$C$9<>""),$C$2:$C$9)=C48)) -> 0
A49: 안전사고 제로(ZERO) | B49: =SUMPRODUCT(--(LOOKUP(ROW($B$2:$B$9),ROW($B$2:$B$9)/($B$2:$B$9<>""),$B$2:$B$9)=A49)) -> 0 | C49: 선제적·체계적 시설관리 운영 | D49: =SUMPRODUCT(--(LOOKUP(ROW($C$2:$C$9),ROW($C$2:$C$9)/($C$2:$C$9<>""),$C$2:$C$9)=C49)) -> 0 | E49: =SUM(D49:D53)-B49 -> 0
C50: 노후, 낙후 시설보수 정비 | D50: =SUMPRODUCT(--(LOOKUP(ROW($C$2:$C$9),ROW($C$2:$C$9)/($C$2:$C$9<>""),$C$2:$C$9)=C50)) -> 0
C51: 「생활쓰레기 일일수거」 | D51: =SUMPRODUCT(--(LOOKUP(ROW($C$2:$C$9),ROW($C$2:$C$9)/($C$2:$C$9<>""),$C$2:$C$9)=C51)) -> 0
C52: 「시설물통합정보관리시스템」 구축 | D52: =SUMPRODUCT(--(LOOKUP(ROW($C$2:$C$9),ROW($C$2:$C$9)/($C$2:$C$9<>""),$C$2:$C$9)=C52)) -> 0
C53: 산업안전보건시스템 | D53: =SUMPRODUCT(--(LOOKUP(ROW($C$2:$C$9),ROW($C$2:$C$9)/($C$2:$C$9<>""),$C$2:$C$9)=C53)) -> 0
A54: 고객만족도 90% 이상 | B54: =SUMPRODUCT(--(LOOKUP(ROW($B$2:$B$9),ROW($B$2:$B$9)/($B$2:$B$9<>""),$B$2:$B$9)=A54)) -> 0 | C54: 환경 민원 신속 처리(‘26년 시행) | D54: =SUMPRODUCT(--(LOOKUP(ROW($C$2:$C$9),ROW($C$2:$C$9)/($C$2:$C$9<>""),$C$2:$C$9)=C54)) -> 0 | E54: =SUM(D54:D59)-B54 -> 0
C55: 각종 시설물관리 운영 전문화 | D55: =SUMPRODUCT(--(LOOKUP(ROW($C$2:$C$9),ROW($C$2:$C$9)/($C$2:$C$9<>""),$C$2:$C$9)=C55)) -> 0
C56: 원활한 주차장 관리 | D56: =SUMPRODUCT(--(LOOKUP(ROW($C$2:$C$9),ROW($C$2:$C$9)/($C$2:$C$9<>""),$C$2:$C$9)=C56)) -> 0
C57: 다양한 시민참여 프로그램 운영 | D57: =SUMPRODUCT(--(LOOKUP(ROW($C$2:$C$9),ROW($C$2:$C$9)/($C$2:$C$9<>""),$C$2:$C$9)=C57)) -> 0
C58: 광고수익증대·도시미관 조성 | D58: =SUMPRODUCT(--(LOOKUP(ROW($C$2:$C$9),ROW($C$2:$C$9)/($C$2:$C$9<>""),$C$2:$C$9)=C58)) -> 0
C59: 노인일자리 창출 및 확대 | D59: =SUMPRODUCT(--(LOOKUP(ROW($C$2:$C$9),ROW($C$2:$C$9)/($C$2:$C$9<>""),$C$2:$C$9)=C59)) -> 0
B60: =SUM(B38:B59) -> 7 | D60: =SUM(D38:D59) -> 7

Sheet 환경사업팀
A1: 환경사업팀 2026년 주요업무계획 추진현황 보고
A2: 연번 | B2: 경영목표 | C2: 전략과제 | D2: 사업 구분 | E2: 추진과제 | F2: 배점 | G2: 이행현황(%) | I2: 점수 | J2: 추진내용 | K2: 문서번호 | L2: 추진일 | M2: 비 고
A3: 1 | B3: =A37 -> 경영평가 "나"등급 이상 | C3: =C37 -> 엄정한 지휘체계 확립 | D3: 신규 | E3: 환경직 직원 복무관리(연차 등)체계 확립 | F3: 10 | G3: 추진중 | H3: 0 | I3: =F3*H3 -> 0
A4: 2 | C4: =C38 -> 중장기경영 전략계획 수립 | D4: 지속 | E4: 종량제봉투 및 음식물류 납부필증 판매 전수조사 | F4: 10 | G4: 추진중 | H4: 0 | I4: =F4*H4 -> 0
A5: 3 | C5: =C42 -> 지역사회공헌 확대 | D5: 신규 | E5: 생활폐기물 적정배출 공익캠페인 활동 | F5: 10 | G5: 추진중 | H5: 0 | I5: =F5*H5 -> 0
A6: 4 | B6: =A43 -> 노사화합 청렴도 우수 등급 | C6: =C43 -> 합리적인 조직관리 | D6: 신규 | E6: 환경사업팀 차량 및 인력 데이터베이스 시스템 구축 | F6: 10 | G6: 추진중 | H6: 0 | I6: =F6*H6 -> 0
A7: 5 | C7: =C45 -> 노사·노노간 상생문화 구축 | D7: 지속 | E7: 노･사 상생을 위한 화합의 장 마련 | F7: 5 | G7: 추진완료 | H7: 1 | I7: =F7*H7 -> 5 | J7: 2026년 월간 노사 "톡톡(Talk Talk)" 화합의 날 운영 | K7: 환경사업팀-620 환경사업팀-1087 환경사업팀-1849 환경사업팀-2748 | L7: 2026.2.6. 2026.3.9. 2026.4.17. 2026.6.12. | M7: 2026년 2월, 3월, 4월, 6월 노사톡톡 화합의 날 운영
A8: 6 | D8: 신규 | E8: 광산구 생활·음식 수거체계 개편 추진 | F8: 10 | G8: 추진중 | H8: 0 | I8: =F8*H8 -> 0
A9: 7 | D9: 지속 | E9: 환경직 참여형 청소차량 설명회 개최 | F9: 5 | G9: 추진완료 | H9: 1 | I9: =F9*H9 -> 5 | J9: 2026년 신규 청소차량 구입 관련 설명회 진행 | K9: 환경사업팀-325 | L9: 2026.1.20. | M9: 신규 청소차량 구입 관련 설명회 실시
A10: 8 | D10: 지속 | E10: 노후화 청소차량 감정평가 및 매각 실시 | F10: 10 | G10: 추진완료 | H10: 1 | I10: =F10*H10 -> 10 | J10: 불용결정 대상 청소차량 7대 감정평가 실시 및 매각 진행 | K10: 환경사업팀-2134 환경사업팀-2872 | L10: 2026.4.27. 2026.6.22. | M10: 매각대금 납부
A11: 9 | C11: =C46 -> 환경직 복리후생 점검 및 개선 | D11: 지속 | E11: 시설 환경정비 및 유지보수 시행 | F11: 5 | G11: 추진완료 | H11: 1 | I11: =F11*H11 -> 5 | J11: 생활환경종합센터 보일러실 전기온수기 수선 생활환경종합센터 내 예초작업 생활환경종합센터 회의실 방음벽 설치 | K11: 환경사업팀-1323 환경사업팀-2793 환경사업팀-3078 | L11: 2026.3.23. 2026.6.6. 2026.7.2. | M11: 생활환경종합센터 보일러실 전기온수기 구매 생활환경종합센터 내 주차장 주변 예초 생활환경종합센터 내 회의실 방음벽 설치
A12: 10 | D12: 신규 | E12: 혹서기, 혹한기 대비 근로자 복리후생 체계 확립 | F12: 10 | G12: 추진중 | H12: 0.5 | I12: =F12*H12 -> 5 | J12: 한랭질환 및 온열질환 예방용품 구입 온열질환 예방을 위한 상생과 화합의 행복 행사 실시 | K12: 환경사업팀-94 환경사업팀-498 환경사업팀-553 환경사업팀-3019 환경사업팀-3051 | L12: 2026.1.8. 2026.1.30. 2026.2.3. 2026.6.30. 2026.7.1. | M12: 환경직 휴대용 모래주머니 구입 '환경직 방한장갑 구입 물끓이기 구입 온열질환 예방용품(팔토시) 구입 냉음료 및 아이스크림 제공
A13: 11 | B13: =A48 -> 안전사고 제로(ZERO) | C13: =C50 -> 「생활쓰레기 일일수거」 | D13: 신규 | E13: 생활폐기물 수집·운반 업무 현장 복무점검 강화 | F13: 10 | G13: 추진완료 | H13: 1 | I13: =F13*H13 -> 10 | J13: 환경사업팀 현장지도·점검 실시 | K13: 환경사업팀-928 환경사업팀-1179 환경사업팀-1669 환경사업팀-1837 환경사업팀-1862 환경사업팀-1866 환경사업팀-2025 환경사업팀-2353 환경사업팀-2429 환경사업팀-2606 환경사업팀-2862 | L13: 2026.2.26. 2026.3.14. 2026.4.7. 2026.4.10. 2026.4.14. 2026.4.18. 2026.4.27. 2026.5.19. 2026.5.23. 2026.6.1. 2026.6.20. | M13: 환경사업팀 현장지도·점검 실시 생활폐기물 혼합배출 현장 계도 및 적정배출 홍보
A14: 12 | D14: 지속 | E14: 효율적 운영을 위한 환경직 순환배치 관리·운영 | F14: 5 | G14: 추진중 | H14: 0.5 | I14: =F14*H14 -> 2.5 | J14: 2026년 상반기 환경직(탑승원) 순환배치 2026년 환경직(운전원) 순환배치 | K14: 환경사업팀-1386 환경사업팀-3203 | L14: 2026.3.25. 2026.7.8. | M14: 탑승원 및 운전원 순환배치 실시
A15: 13 | D15: 지속 | E15: 일일수거제 지속 관리·운영으로 미수거 민원 최소화 | F15: 10 | G15: 추진중 | H15: 0 | I15: =F15*H15 -> 0
A16: 14 | B16: =A53 -> 고객만족도 90% 이상 | C16: =C56 -> 다양한 시민참여 프로그램 운영 | D16: 지속 | E16: 기후위기대응을 위한 시민참여 프로그램 추진 | F16: 10 | G16: 추진중 | H16: 0.5 | I16: =F16*H16 -> 5 | J16: 시민 참여형 기후적응 정책개발 업무협약 진행 | K16: 환경사업팀-1210 | L16: 2026.3.16. | M16: 시민참여형 기후적응 리빙랩사업 업무협약 진행
F18: 총점 | G18: 점수 | H18: 환산점수(100점만점)
F19: =SUM(F3:F16) -> 120 | G19: =SUM(I3:I16) -> 47.5 | H19: =G19/F19*100 -> 39.583333
H20: =AVERAGE($H$3:H16) -> 0.46428571
C32: 지속여부 | D32: 지속
D33: =COUNTIF(D3:D31,$D$32) -> 8
D34: 신규
D35: =COUNTIF(D3:D33,$D$34) -> 6
A36: 경영목표 | C36: 경영전략
A37: 경영평가 "나"등급 이상 | B37: =SUMPRODUCT(--(LOOKUP(ROW($B$2:$B$16),ROW($B$2:$B$16)/($B$2:$B$16<>""),$B$2:$B$16)=A37)) -> 3 | C37: 엄정한 지휘체계 확립 | D37: =SUMPRODUCT(--(LOOKUP(ROW($C$2:$C$16),ROW($C$2:$C$16)/($C$2:$C$16<>""),$C$2:$C$16)=C37)) -> 1 | E37: =SUM(D37:D42)-B37 -> 0
C38: 중장기경영 전략계획 수립 | D38: =SUMPRODUCT(--(LOOKUP(ROW($C$2:$C$16),ROW($C$2:$C$16)/($C$2:$C$16<>""),$C$2:$C$16)=C38)) -> 1
C39: 건전재정운영 예산집행 투명성 | D39: =SUMPRODUCT(--(LOOKUP(ROW($C$2:$C$16),ROW($C$2:$C$16)/($C$2:$C$16<>""),$C$2:$C$16)=C39)) -> 0
C40: 독립적 감사 기능 강화 | D40: =SUMPRODUCT(--(LOOKUP(ROW($C$2:$C$16),ROW($C$2:$C$16)/($C$2:$C$16<>""),$C$2:$C$16)=C40)) -> 0
C41: 개인정보 보호 관리 철저 | D41: =SUMPRODUCT(--(LOOKUP(ROW($C$2:$C$16),ROW($C$2:$C$16)/($C$2:$C$16<>""),$C$2:$C$16)=C41)) -> 0
C42: 지역사회공헌 확대 | D42: =SUMPRODUCT(--(LOOKUP(ROW($C$2:$C$16),ROW($C$2:$C$16)/($C$2:$C$16<>""),$C$2:$C$16)=C42)) -> 1
A43: 노사화합 청렴도 우수 등급 | B43: =SUMPRODUCT(--(LOOKUP(ROW($B$2:$B$16),ROW($B$2:$B$16)/($B$2:$B$16<>""),$B$2:$B$16)=A43)) -> 7 | C43: 합리적인 조직관리 | D43: =SUMPRODUCT(--(LOOKUP(ROW($C$2:$C$16),ROW($C$2:$C$16)/($C$2:$C$16<>""),$C$2:$C$16)=C43)) -> 1 | E43: =SUM(D43:D47)-B43 -> 0
C44: 합리적 승진 전보제도 | D44: =SUMPRODUCT(--(LOOKUP(ROW($C$2:$C$16),ROW($C$2:$C$16)/($C$2:$C$16<>""),$C$2:$C$16)=C44)) -> 0
C45: 노사·노노간 상생문화 구축 | D45: =SUMPRODUCT(--(LOOKUP(ROW($C$2:$C$16),ROW($C$2:$C$16)/($C$2:$C$16<>""),$C$2:$C$16)=C45)) -> 4
C46: 환경직 복리후생 점검 및 개선 | D46: =SUMPRODUCT(--(LOOKUP(ROW($C$2:$C$16),ROW($C$2:$C$16)/($C$2:$C$16<>""),$C$2:$C$16)=C46)) -> 2
C47: 합리적 보수(임금) 유지 | D47: =SUMPRODUCT(--(LOOKUP(ROW($C$2:$C$16),ROW($C$2:$C$16)/($C$2:$C$16<>""),$C$2:$C$16)=C47)) -> 0
A48: 안전사고 제로(ZERO) | B48: =SUMPRODUCT(--(LOOKUP(ROW($B$2:$B$16),ROW($B$2:$B$16)/($B$2:$B$16<>""),$B$2:$B$16)=A48)) -> 3 | C48: 선제적·체계적 시설관리 운영 | D48: =SUMPRODUCT(--(LOOKUP(ROW($C$2:$C$16),ROW($C$2:$C$16)/($C$2:$C$16<>""),$C$2:$C$16)=C48)) -> 0 | E48: =SUM(D48:D52)-B48 -> 0
C49: 노후, 낙후 시설보수 정비 | D49: =SUMPRODUCT(--(LOOKUP(ROW($C$2:$C$16),ROW($C$2:$C$16)/($C$2:$C$16<>""),$C$2:$C$16)=C49)) -> 0
C50: 「생활쓰레기 일일수거」 | D50: =SUMPRODUCT(--(LOOKUP(ROW($C$2:$C$16),ROW($C$2:$C$16)/($C$2:$C$16<>""),$C$2:$C$16)=C50)) -> 3
C51: 「시설물통합정보관리시스템」 구축 | D51: =SUMPRODUCT(--(LOOKUP(ROW($C$2:$C$16),ROW($C$2:$C$16)/($C$2:$C$16<>""),$C$2:$C$16)=C51)) -> 0
C52: 산업안전보건시스템 | D52: =SUMPRODUCT(--(LOOKUP(ROW($C$2:$C$16),ROW($C$2:$C$16)/($C$2:$C$16<>""),$C$2:$C$16)=C52)) -> 0
...

Sheet 행복나루
A1: 행복나루노인복지관 2026년 주요업무계획 추진현황 보고
A2: 연번 | B2: 경영목표 | C2: 전략과제 | D2: 사업 구분 | E2: 추진과제 | F2: 배점 | G2: 이행현황(%) | I2: 점수 | J2: 추진내용 | K2: 문서번호 | L2: 추진일 | M2: 비 고
A3: 1 | B3: =A35 -> 경영평가 "나"등급 이상 | C3: =C40 -> 지역사회공헌 확대 | D3: 지속 | E3: 지역소멸 극복 테마문화 나들이 | F3: 6 | G3: 추진중 | H3: 0.25 | I3: 1.5 | J3: 테마가 있는 문화나들이 1회추진 | K3: 노인복자관-2286, 2616 | L3: 2026. 6. 11.
A4: 2 | D4: 신규 | E4: 자원순환 플리마켓 ‘RE:MARKET’ | F4: 5 | G4: 추진중 | H4: 0 | I4: 0 | J4: 10월 추진 예정 | L4: 3~7월
A5: 3 | D5: 신규 | E5: 지구지킴이가 그린지9 월별 챌린지 실천 | F5: 10 | G5: 추진중 | H5: 1 | I5: 10 | J5: 친환경리필스테이션, 페트병 분리배출, 지구의날캠페인, 비건day, 에너지절약캠페인, 세계물의날 하수처리장 견학, 카페라떼클럽 등 지속 | K5: 노인복지관-1089, 1428, 1734, 1981, 3091 | L5: 1~6월
A6: 4 | D6: 지속 | E6: 맞춤형 건강상담서비스 ‘건강톡(talk)’ 추진 | F6: 10 | G6: 추진중 | H6: 0.24 | I6: 2.4 | J6: 지역밀착형 찾아가는 마을복지관 건강상담 추진 | K6: 노인복지관-2638, 3029, 3288 | L6: 6~7월
A7: 5 | B7: 노사화합 청렴도 우수 등급 | C7: 합리적인 조직관리 | D7: 신규 | E7: “복지에 철학을 담다” 역량강화교육 | F7: 6 | G7: 추진중 | H7: 0.5 | I7: 3 | J7: 복지에 철학을 담다 독서토론, 시청각 교육 | K7: 노인복지관-1402, 2655 | L7: 2026. 03. 25. 2026. 05. 29.
A8: 6 | D8: 지속 | E8: 미래혁신경영 종사자 수퍼비전 | F8: 6 | G8: 추진중 | H8: 0.35 | I8: 3 | J8: 1분기 직원수퍼비전 추진결과보고 | K8: 노인복지관-2054 | L8: 2026. 05. 12.
A9: 7 | D9: 신규 | E9: 신바람 행복나루 “동고동락” 프로젝트 | F9: 6 | G9: 추진완료 | H9: 1 | I9: 6 | J9: 직원대상 동고동락 2회 추진, 선진지견학 2회 | K9: 노인복지관-1831, 3193, | L9: 2026. 04. 28.
A10: 8 | B10: 안전사고 제로(ZERO) | C10: 선제적·체계적 시설관리 운영 | D10: 지속 | E10: 경로식당 위생안전사고 제로 추진 | F10: 6 | G10: 추진중 | H10: 1 | I10: 6 | J10: 안전사고 미발생 | K10: 해당없음 | L10: 해당없음
A11: 9 | B11: 고객만족도 90% 이상 | C11: 각종 시설물관리 운영 전문화 | D11: 신규 | E11: 디지털 기술(AI)활용 프로그램 운영 | F11: 8 | G11: 추진중 | H11: 0.75 | I11: 6 | J11: '찾아가는 스마트교육 에듀버스', 스마트폰 생활반 운영 | K11: 노인복지관-2677, 1892 | L11: 2026. 06. 17. 2026. 05. 04.
A12: 10 | D12: 지속 | E12: 존엄한 마무리, 아름다운 선택 웰다잉 프로그램 | F12: 8 | G12: 추진예정 | H12: 0.37 | I12: 2.96 | J12: 사전연명의료의향서 283건 등록
A13: 11 | D13: 신규 | E13: 맞춤형 여가프로그램 신설 | F13: 6 | G13: 추진중 | H13: 0.5 | I13: 3 | J13: 2026년 노년사회화교육 프로그램 신설- 크로스핏, 생활영어 회화, 합창, '삼색 꽃 매듭(사진) | K13: 노인복지관-5762,2324, 3218 | L13: 2025. 12. 19. 2026. 05. 28. 2026. 07. 16.
A14: 12 | D14: 지속 | E14: 독거노인 식생활 건강지원 요리교실 | F14: 8 | G14: 추진중 | H14: 1 | I14: 8 | J14: 홀몸남성 이용자 식사 자립 이웃 나눔 프로젝트-'요리조리 맨(MAN)드러' | K14: 노인복지관-1763 | L14: 2026. 04. 27.
A15: 13 | D15: 지속 | E15: 건강지원 영양상담교육 | F15: 8 | G15: 추진중 | H15: 0.2 | I15: 1.6 | J15: 2026년 찾아가는 마을 복지관 영양상담 | K15: 노인복지관-2498 | L15: 2026. 06. 09.
A16: 14 | D16: 지속 | E16: 노인 결식우려예방 경로식당운영 | F16: 8 | G16: 추진중 | H16: 0.504 | I16: 4.032 | J16: 결식우려 예방 및 균형잡힌 식단 제공을 위한 6월 사랑의 식당 운영 결과보고 | K16: 노인복지관-2952 | L16: 2026.07.01.
A17: 15 | D17: 지속 | E17: 이용자 편의 및 안전을 위한 시설관리 | F17: 6 | G17: 추진중 | H17: 0.5 | I17: 3 | J17: 1, 2분기 시설안전점검 실시 | K17: 노인복지관-1987, 2755 | L17: 2026. 05. 07. 2026. 06. 18.
A18: 16 | D18: 지속 | E18: 정신건강선별 검사 및 상담 심리정서지원서비스 추진 | F18: 10 | G18: 추진중 | H18: 0.64 | I18: 6.4 | J18: 정신선강선별검사 및 상담 | K18: 노인복지관-169, 825, 1265, 1794, 2426 | L18: 3월~7월
A19: 17 | C19: =C54 -> 다양한 시민참여 프로그램 운영 | D19: 지속 | E19: 은퇴세대 맞춤형 프로그램 “꽃중년 아카데미” | F19: 8 | G19: 추진중 | H19: 0.875 | I19: 7 | J19: 2026년 상반기 신노년 맞춤프로그램'꽃중년아카데미'운영 결과보고 | K19: 노인복지관-2187 | L19: 2026. 05. 20.
A20: 18 | D20: 신규 | E20: 세대공감 프로젝트 ‘서로ON(온)’ | F20: 10 | G20: 추진중 | H20: 1 | I20: 10 | J20: 친절문화확산캠페인 및 옛전남도청전시관 탐방, 디지털 세대공감 함께이음 ai교실 | K20: 노인복지관-1581, 2236, 2648 | L20: 3월~7월
A21: 19 | D21: 지속 | E21: 밤에도 열리는 야호마을복지관 ‘밤마실’ 운영 | F21: 5 | G21: 추진중 | H21: 1 | I21: 5 | J21: 야간마을복지관 운영, 탁구, 헬스, 밤마실요가, 밤마실라인댄스 운영 | K21: 노인복지관-536, 892, 1812, 1969, 2855, 3033 | L21: 2월~7월
A22: 20 | D22: 지속 | E22: 기억보감 프로젝트 ‘뇌마음에 보약’ | F22: 10 | G22: 추진중 | H22: 0.64 | I22: 6.4 | J22: 치매예방을 위한 뇌반짝교실 추진 | K22: 노인복지관-700, 1264, 2063, 2579, 3018 | L22: 3월~7월
F25: 총점 | G25: 점수 | H25: 환산점수(100점만점)
F26: =SUM(F3:F22) -> 150 | G26: =SUM(I3:I22) -> 95.292 | H26: =G26/F26*100 -> 63.528
H27: =AVERAGE($H$3:H23) -> 0.61595
C30: 지속여부 | D30: 지속
D31: =COUNTIF(D3:D29,$D$30) -> 13
D32: 신규
D33: =COUNTIF(D3:D31,$D$32) -> 7
A34: 경영목표 | C34: 경영전략
A35: 경영평가 "나"등급 이상 | B35: =SUMPRODUCT(--(LOOKUP(ROW($B$2:$B$22),ROW($B$2:$B$22)/($B$2:$B$22<>""),$B$2:$B$22)=A35)) -> 4 | C35: 엄정한 지휘체계 확립 | D35: =SUMPRODUCT(--(LOOKUP(ROW($C$2:$C$22),ROW($C$2:$C$22)/($C$2:$C$22<>""),$C$2:$C$22)=C35)) -> 0 | E35: =SUM(D35:D40)-B35 -> 0
C36: 중장기경영 전략계획 수립 | D36: =SUMPRODUCT(--(LOOKUP(ROW($C$2:$C$22),ROW($C$2:$C$22)/($C$2:$C$22<>""),$C$2:$C$22)=C36)) -> 0
C37: 건전재정운영 예산집행 투명성 | D37: =SUMPRODUCT(--(LOOKUP(ROW($C$2:$C$22),ROW($C$2:$C$22)/($C$2:$C$22<>""),$C$2:$C$22)=C37)) -> 0
C38: 독립적 감사 기능 강화 | D38: =SUMPRODUCT(--(LOOKUP(ROW($C$2:$C$22),ROW($C$2:$C$22)/($C$2:$C$22<>""),$C$2:$C$22)=C38)) -> 0
C39: 개인정보 보호 관리 철저 | D39: =SUMPRODUCT(--(LOOKUP(ROW($C$2:$C$22),ROW($C$2:$C$22)/($C$2:$C$22<>""),$C$2:$C$22)=C39)) -> 0
C40: 지역사회공헌 확대 | D40: =SUMPRODUCT(--(LOOKUP(ROW($C$2:$C$22),ROW($C$2:$C$22)/($C$2:$C$22<>""),$C$2:$C$22)=C40)) -> 4
A41: 노사화합 청렴도 우수 등급 | B41: =SUMPRODUCT(--(LOOKUP(ROW($B$2:$B$22),ROW($B$2:$B$22)/($B$2:$B$22<>""),$B$2:$B$22)=A41)) -> 3 | C41: 합리적인 조직관리 | D41: =SUMPRODUCT(--(LOOKUP(ROW($C$2:$C$22),ROW($C$2:$C$22)/($C$2:$C$22<>""),$C$2:$C$22)=C41)) -> 3 | E41: =SUM(D41:D45)-B41 -> 0
C42: 합리적 승진 전보제도 | D42: =SUMPRODUCT(--(LOOKUP(ROW($C$2:$C$22),ROW($C$2:$C$22)/($C$2:$C$22<>""),$C$2:$C$22)=C42)) -> 0
C43: 노사·노노간 상생문화 구축 | D43: =SUMPRODUCT(--(LOOKUP(ROW($C$2:$C$22),ROW($C$2:$C$22)/($C$2:$C$22<>""),$C$2:$C$22)=C43)) -> 0
C44: 환경직 복리후생 점검 및 개선 | D44: =SUMPRODUCT(--(LOOKUP(ROW($C$2:$C$22),ROW($C$2:$C$22)/($C$2:$C$22<>""),$C$2:$C$22)=C44)) -> 0
...
